<?xml version='1.0' encoding='UTF-8'?>
<!-- 
#####################################################################################
#
# Copyright (c) 2023-2025 Galbot, Inc. All Rights Reserved.
#
# This software contains confidential and proprietary information of Galbot, Inc.
# ("Confidential Information"). You shall not disclose such Confidential Information
# and shall use it only in accordance with the terms of the license agreement you
# entered into with Galbot, Inc.
#
# UNAUTHORIZED COPYING, USE, OR DISTRIBUTION OF THIS SOFTWARE, OR ANY PORTION OR
# DERIVATIVE THEREOF, IS STRICTLY PROHIBITED. IF YOU HAVE RECEIVED THIS SOFTWARE IN
# ERROR, PLEASE NOTIFY GALBOT, INC. IMMEDIATELY AND DELETE IT FROM YOUR SYSTEM.
#
#####################################################################################
#
# Description: XACRO file for hitbot gripper.
# Maintainer: Herman Ye, Yuhao Zeng@Galbot
#
#####################################################################################
-->
<robot xmlns:xacro="http://ros.org/wiki/xacro" name="hitbot_gripper">

  <xacro:macro name="hitbot_gripper"
    params="parent *origin name:=hitbot_gripper collision_type:=convex_decomposition">
    <xacro:property name="M_PI" value="3.1415926535897931" />

    <joint name="${name}_joint" type="fixed">
      <xacro:insert_block name="origin" />
      <parent link="${parent}" />
      <child link="${name}_base_link" />
    </joint>

    <link name="${name}_base_link">
      <inertial>
        <origin xyz="0.0828 0.03604 -7.000000000000001e-05" rpy="0 0 0" />
        <mass value="0.878" />
        <inertia ixx="0.0011546199999999999" ixy="0.0026213200000000003"
          ixz="-5.0899999999999995e-06" iyy="0.00603809" iyz="-2.31e-06" izz="0.0071770900000000006" />
      </inertial>
      <visual>
        <origin xyz="0 0 0" rpy="0 0 0" />
        <geometry>
          <mesh
            filename="package://galbot_one_golf_description/meshes/visual/gripper/hitbot_gripper/base_link/obj/base_link.obj" />
        </geometry>
      </visual>
      <xacro:if value="${collision_type == 'sphere'}">
        <collision>
          <origin xyz="0 0 0" rpy="0 0 0" />
          <geometry>
            <sphere radius="0.05" />
          </geometry>
        </collision>
      </xacro:if>
      <xacro:if value="${collision_type == 'mesh'}">
        <collision>
          <origin xyz="0 0 0" rpy="0 0 0" />
          <geometry>
            <mesh
              filename="package://galbot_one_golf_description/meshes/collision/gripper/hitbot_gripper/base_link/original/base_link.stl" />
          </geometry>
        </collision>
      </xacro:if>
      <xacro:if value="${collision_type == 'convex_hull'}">
        <collision>
          <origin xyz="0 0 0" rpy="0 0 0" />
          <geometry>
            <mesh
              filename="package://galbot_one_golf_description/meshes/collision/gripper/hitbot_gripper/base_link/convex_hull/base_link_convex_hull.stl" />
          </geometry>
        </collision>
      </xacro:if>
      <xacro:if value="${collision_type == 'convex_decomposition'}">
        <collision>
          <origin xyz="0 0 0" rpy="0 0 0" />
          <geometry>
            <mesh
              filename="package://galbot_one_golf_description/meshes/collision/gripper/hitbot_gripper/base_link/convex_decomposition/base_link_convex_decomposition_0.stl" />
          </geometry>
        </collision>
        <collision>
          <origin xyz="0 0 0" rpy="0 0 0" />
          <geometry>
            <mesh
              filename="package://galbot_one_golf_description/meshes/collision/gripper/hitbot_gripper/base_link/convex_decomposition/base_link_convex_decomposition_1.stl" />
          </geometry>
        </collision>
        <collision>
          <origin xyz="0 0 0" rpy="0 0 0" />
          <geometry>
            <mesh
              filename="package://galbot_one_golf_description/meshes/collision/gripper/hitbot_gripper/base_link/convex_decomposition/base_link_convex_decomposition_2.stl" />
          </geometry>
        </collision>
        <collision>
          <origin xyz="0 0 0" rpy="0 0 0" />
          <geometry>
            <mesh
              filename="package://galbot_one_golf_description/meshes/collision/gripper/hitbot_gripper/base_link/convex_decomposition/base_link_convex_decomposition_3.stl" />
          </geometry>
        </collision>
      </xacro:if>
    </link>

    <link name="${name}_link1">
      <inertial>
        <origin xyz="0.01927 -0.00066 -0.00023999999999999998" rpy="0 0 0" />
        <mass value="0.0312" />
        <inertia ixx="2.53e-06" ixy="3.8e-07" ixz="3e-08" iyy="2.928e-05" iyz="6e-08"
          izz="2.795e-05" />
      </inertial>
      <visual>
        <origin xyz="0 0 0" rpy="0 0 0" />
        <geometry>
          <mesh
            filename="package://galbot_one_golf_description/meshes/visual/gripper/hitbot_gripper/gripper_link1/obj/gripper_link1.obj" />
        </geometry>
      </visual>
      <xacro:if value="${collision_type == 'sphere'}">
        <collision>
          <origin xyz="0 0 0" rpy="0 0 0" />
          <geometry>
            <sphere radius="0.05" />
          </geometry>
        </collision>
      </xacro:if>
      <xacro:if value="${collision_type == 'mesh'}">
        <collision>
          <origin xyz="0 0 0" rpy="0 0 0" />
          <geometry>
            <mesh
              filename="package://galbot_one_golf_description/meshes/collision/gripper/hitbot_gripper/gripper_link1/original/gripper_link1.stl" />
          </geometry>
        </collision>
      </xacro:if>
      <xacro:if value="${collision_type == 'convex_hull'}">
        <collision>
          <origin xyz="0 0 0" rpy="0 0 0" />
          <geometry>
            <mesh
              filename="package://galbot_one_golf_description/meshes/collision/gripper/hitbot_gripper/gripper_link1/convex_hull/gripper_link1_convex_hull.stl" />
          </geometry>
        </collision>
      </xacro:if>
      <xacro:if value="${collision_type == 'convex_decomposition'}">
        <collision>
          <origin xyz="0 0 0" rpy="0 0 0" />
          <geometry>
            <mesh
              filename="package://galbot_one_golf_description/meshes/collision/gripper/hitbot_gripper/gripper_link1/convex_decomposition/gripper_link1_convex_decomposition_0.stl" />
          </geometry>
        </collision>
        <collision>
          <origin xyz="0 0 0" rpy="0 0 0" />
          <geometry>
            <mesh
              filename="package://galbot_one_golf_description/meshes/collision/gripper/hitbot_gripper/gripper_link1/convex_decomposition/gripper_link1_convex_decomposition_1.stl" />
          </geometry>
        </collision>
        <collision>
          <origin xyz="0 0 0" rpy="0 0 0" />
          <geometry>
            <mesh
              filename="package://galbot_one_golf_description/meshes/collision/gripper/hitbot_gripper/gripper_link1/convex_decomposition/gripper_link1_convex_decomposition_2.stl" />
          </geometry>
        </collision>
      </xacro:if>
    </link>

    <joint name="${name}_joint1" type="revolute">
      <origin xyz="0.12183 -0.02 0" rpy="${M_PI} 0 ${-M_PI/4}" />
      <parent link="${name}_base_link" />
      <child link="${name}_link1" />
      <axis xyz="0 0 -1" />
      <limit lower="-6.28" upper="6.28" velocity="2.0" effort="50" /> <!-- Fake effort and velocity
      for
      gripper -->
    </joint>

    <link name="${name}_link2">
      <inertial>
        <origin xyz="0.02767 -0.0 -0.0" rpy="0 0 0" />
        <mass value="0.0168" />
        <inertia ixx="1.25e-06" ixy="0.0" ixz="0.0" iyy="2.284e-05" iyz="0.0" izz="2.175e-05" />
      </inertial>
      <visual>
        <origin xyz="0 0 0" rpy="0 0 0" />
        <geometry>
          <mesh
            filename="package://galbot_one_golf_description/meshes/visual/gripper/hitbot_gripper/gripper_link2/obj/gripper_link2.obj" />
        </geometry>
      </visual>
      <xacro:if value="${collision_type == 'sphere'}">
        <collision>
          <origin xyz="0 0 0" rpy="0 0 0" />
          <geometry>
            <sphere radius="0.05" />
          </geometry>
        </collision>
      </xacro:if>
      <xacro:if value="${collision_type == 'mesh'}">
        <collision>
          <origin xyz="0 0 0" rpy="0 0 0" />
          <geometry>
            <mesh
              filename="package://galbot_one_golf_description/meshes/collision/gripper/hitbot_gripper/gripper_link2/original/gripper_link2.stl" />
          </geometry>
        </collision>
      </xacro:if>
      <xacro:if value="${collision_type == 'convex_hull'}">
        <collision>
          <origin xyz="0 0 0" rpy="0 0 0" />
          <geometry>
            <mesh
              filename="package://galbot_one_golf_description/meshes/collision/gripper/hitbot_gripper/gripper_link2/convex_hull/gripper_link2_convex_hull.stl" />
          </geometry>
        </collision>
      </xacro:if>
      <xacro:if value="${collision_type == 'convex_decomposition'}">
        <collision>
          <origin xyz="0 0 0" rpy="0 0 0" />
          <geometry>
            <mesh
              filename="package://galbot_one_golf_description/meshes/collision/gripper/hitbot_gripper/gripper_link2/convex_decomposition/gripper_link2_convex_decomposition_0.stl" />
          </geometry>
        </collision>
        <collision>
          <origin xyz="0 0 0" rpy="0 0 0" />
          <geometry>
            <mesh
              filename="package://galbot_one_golf_description/meshes/collision/gripper/hitbot_gripper/gripper_link2/convex_decomposition/gripper_link2_convex_decomposition_1.stl" />
          </geometry>
        </collision>
        <collision>
          <origin xyz="0 0 0" rpy="0 0 0" />
          <geometry>
            <mesh
              filename="package://galbot_one_golf_description/meshes/collision/gripper/hitbot_gripper/gripper_link2/convex_decomposition/gripper_link2_convex_decomposition_2.stl" />
          </geometry>
        </collision>
        <collision>
          <origin xyz="0 0 0" rpy="0 0 0" />
          <geometry>
            <mesh
              filename="package://galbot_one_golf_description/meshes/collision/gripper/hitbot_gripper/gripper_link2/convex_decomposition/gripper_link2_convex_decomposition_3.stl" />
          </geometry>
        </collision>
        <collision>
          <origin xyz="0 0 0" rpy="0 0 0" />
          <geometry>
            <mesh
              filename="package://galbot_one_golf_description/meshes/collision/gripper/hitbot_gripper/gripper_link2/convex_decomposition/gripper_link2_convex_decomposition_4.stl" />
          </geometry>
        </collision>
      </xacro:if>
    </link>

    <joint name="${name}_joint2" type="revolute">
      <origin xyz="0.1368 -0.01 0" rpy="${M_PI} 0 ${-M_PI/4}" />
      <parent link="${name}_base_link" />
      <child link="${name}_link2" />
      <axis xyz="0 0 -1" />
      <limit lower="-6.28" upper="6.28" velocity="2.0" effort="50" /> <!-- Fake effort and velocity
      for
      gripper -->
    </joint>

    <link name="${name}_link3">
      <inertial>
        <origin xyz="0.010320000000000001 -0.00034 0.0" rpy="0 0 0" />
        <mass value="0.026000000000000002" />
        <inertia ixx="1.57e-06" ixy="1.92e-06" ixz="0.0" iyy="1.1380000000000001e-05" iyz="0.0"
          izz="1.176e-05" />
      </inertial>
      <visual>
        <origin xyz="0 0 0" rpy="0 0 0" />
        <geometry>
          <mesh
            filename="package://galbot_one_golf_description/meshes/visual/gripper/hitbot_gripper/gripper_link3/obj/gripper_link3.obj" />
        </geometry>
      </visual>
      <xacro:if value="${collision_type == 'sphere'}">
        <collision>
          <origin xyz="0 0 0" rpy="0 0 0" />
          <geometry>
            <sphere radius="0.05" />
          </geometry>
        </collision>
      </xacro:if>
      <xacro:if value="${collision_type == 'mesh'}">
        <collision>
          <origin xyz="0 0 0" rpy="0 0 0" />
          <geometry>
            <mesh
              filename="package://galbot_one_golf_description/meshes/collision/gripper/hitbot_gripper/gripper_link3/original/gripper_link3.stl" />
          </geometry>
        </collision>
      </xacro:if>
      <xacro:if value="${collision_type == 'convex_hull'}">
        <collision>
          <origin xyz="0 0 0" rpy="0 0 0" />
          <geometry>
            <mesh
              filename="package://galbot_one_golf_description/meshes/collision/gripper/hitbot_gripper/gripper_link3/convex_hull/gripper_link3_convex_hull.stl" />
          </geometry>
        </collision>
      </xacro:if>
      <xacro:if value="${collision_type == 'convex_decomposition'}">
        <collision>
          <origin xyz="0 0 0" rpy="0 0 0" />
          <geometry>
            <mesh
              filename="package://galbot_one_golf_description/meshes/collision/gripper/hitbot_gripper/gripper_link3/convex_decomposition/gripper_link3_convex_decomposition_0.stl" />
          </geometry>
        </collision>
        <collision>
          <origin xyz="0 0 0" rpy="0 0 0" />
          <geometry>
            <mesh
              filename="package://galbot_one_golf_description/meshes/collision/gripper/hitbot_gripper/gripper_link3/convex_decomposition/gripper_link3_convex_decomposition_1.stl" />
          </geometry>
        </collision>
      </xacro:if>
    </link>

    <joint name="${name}_joint3" type="revolute">
      <origin xyz="0.065 0 0" rpy="0 0 ${-M_PI/4}" />
      <parent link="${name}_link2" />
      <child link="${name}_link3" />
      <axis xyz="0 0 -1" />
      <limit lower="-6.28" upper="6.28" velocity="2.0" effort="50" /> <!-- Fake effort and velocity
      for
      gripper -->
    </joint>

    <link name="${name}_link4">
      <inertial>
        <origin xyz="0.01927 0.00066 0.00023999999999999998" rpy="0 0 0" />
        <mass value="0.0312" />
        <inertia ixx="2.53e-06" ixy="3.8e-07" ixz="3e-08" iyy="2.928e-05" iyz="6.5e-08"
          izz="2.795e-05" />
      </inertial>
      <visual>
        <origin xyz="0 0 0" rpy="0 0 0" />
        <geometry>
          <mesh
            filename="package://galbot_one_golf_description/meshes/visual/gripper/hitbot_gripper/gripper_link4/obj/gripper_link4.obj" />
        </geometry>
      </visual>
      <xacro:if value="${collision_type == 'sphere'}">
        <collision>
          <origin xyz="0 0 0" rpy="0 0 0" />
          <geometry>
            <sphere radius="0.05" />
          </geometry>
        </collision>
      </xacro:if>
      <xacro:if value="${collision_type == 'mesh'}">
        <collision>
          <origin xyz="0 0 0" rpy="0 0 0" />
          <geometry>
            <mesh
              filename="package://galbot_one_golf_description/meshes/collision/gripper/hitbot_gripper/gripper_link4/original/gripper_link4.stl" />
          </geometry>
        </collision>
      </xacro:if>
      <xacro:if value="${collision_type == 'convex_hull'}">
        <collision>
          <origin xyz="0 0 0" rpy="0 0 0" />
          <geometry>
            <mesh
              filename="package://galbot_one_golf_description/meshes/collision/gripper/hitbot_gripper/gripper_link4/convex_hull/gripper_link4_convex_hull.stl" />
          </geometry>
        </collision>
      </xacro:if>
      <xacro:if value="${collision_type == 'convex_decomposition'}">
        <collision>
          <origin xyz="0 0 0" rpy="0 0 0" />
          <geometry>
            <mesh
              filename="package://galbot_one_golf_description/meshes/collision/gripper/hitbot_gripper/gripper_link4/convex_decomposition/gripper_link4_convex_decomposition_0.stl" />
          </geometry>
        </collision>
        <collision>
          <origin xyz="0 0 0" rpy="0 0 0" />
          <geometry>
            <mesh
              filename="package://galbot_one_golf_description/meshes/collision/gripper/hitbot_gripper/gripper_link4/convex_decomposition/gripper_link4_convex_decomposition_1.stl" />
          </geometry>
        </collision>
        <collision>
          <origin xyz="0 0 0" rpy="0 0 0" />
          <geometry>
            <mesh
              filename="package://galbot_one_golf_description/meshes/collision/gripper/hitbot_gripper/gripper_link4/convex_decomposition/gripper_link4_convex_decomposition_2.stl" />
          </geometry>
        </collision>
      </xacro:if>
    </link>

    <joint name="${name}_joint4" type="revolute">
      <origin xyz="0.121833370678203 0.0199999993241963 0" rpy="${M_PI} 0 ${M_PI/4}" />
      <parent link="${name}_base_link" />
      <child link="${name}_link4" />
      <axis xyz="0 0 -1" />
      <limit lower="-6.28" upper="6.28" velocity="2.0" effort="50" /> <!-- Fake effort and velocity
      for
      gripper -->
    </joint>

    <link name="${name}_link5">
      <inertial>
        <origin xyz="0.02767 0.0 0.0" rpy="0 0 0" />
        <mass value="0.0168" />
        <inertia ixx="1.25e-06" ixy="0.0" ixz="0.0" iyy="2.284e-05" iyz="0.0" izz="2.175e-05" />
      </inertial>
      <visual>
        <origin xyz="0 0 0" rpy="0 0 0" />
        <geometry>
          <mesh
            filename="package://galbot_one_golf_description/meshes/visual/gripper/hitbot_gripper/gripper_link5/obj/gripper_link5.obj" />
        </geometry>
      </visual>
      <xacro:if value="${collision_type == 'sphere'}">
        <collision>
          <origin xyz="0 0 0" rpy="0 0 0" />
          <geometry>
            <sphere radius="0.05" />
          </geometry>
        </collision>
      </xacro:if>
      <xacro:if value="${collision_type == 'mesh'}">
        <collision>
          <origin xyz="0 0 0" rpy="0 0 0" />
          <geometry>
            <mesh
              filename="package://galbot_one_golf_description/meshes/collision/gripper/hitbot_gripper/gripper_link5/original/gripper_link5.stl" />
          </geometry>
        </collision>
      </xacro:if>
      <xacro:if value="${collision_type == 'convex_hull'}">
        <collision>
          <origin xyz="0 0 0" rpy="0 0 0" />
          <geometry>
            <mesh
              filename="package://galbot_one_golf_description/meshes/collision/gripper/hitbot_gripper/gripper_link5/convex_hull/gripper_link5_convex_hull.stl" />
          </geometry>
        </collision>
      </xacro:if>
      <xacro:if value="${collision_type == 'convex_decomposition'}">
        <collision>
          <origin xyz="0 0 0" rpy="0 0 0" />
          <geometry>
            <mesh
              filename="package://galbot_one_golf_description/meshes/collision/gripper/hitbot_gripper/gripper_link5/convex_decomposition/gripper_link5_convex_decomposition_0.stl" />
          </geometry>
        </collision>
        <collision>
          <origin xyz="0 0 0" rpy="0 0 0" />
          <geometry>
            <mesh
              filename="package://galbot_one_golf_description/meshes/collision/gripper/hitbot_gripper/gripper_link5/convex_decomposition/gripper_link5_convex_decomposition_1.stl" />
          </geometry>
        </collision>
        <collision>
          <origin xyz="0 0 0" rpy="0 0 0" />
          <geometry>
            <mesh
              filename="package://galbot_one_golf_description/meshes/collision/gripper/hitbot_gripper/gripper_link5/convex_decomposition/gripper_link5_convex_decomposition_2.stl" />
          </geometry>
        </collision>
        <collision>
          <origin xyz="0 0 0" rpy="0 0 0" />
          <geometry>
            <mesh
              filename="package://galbot_one_golf_description/meshes/collision/gripper/hitbot_gripper/gripper_link5/convex_decomposition/gripper_link5_convex_decomposition_3.stl" />
          </geometry>
        </collision>
        <collision>
          <origin xyz="0 0 0" rpy="0 0 0" />
          <geometry>
            <mesh
              filename="package://galbot_one_golf_description/meshes/collision/gripper/hitbot_gripper/gripper_link5/convex_decomposition/gripper_link5_convex_decomposition_4.stl" />
          </geometry>
        </collision>
      </xacro:if>
    </link>

    <joint name="${name}_joint5" type="revolute">
      <origin xyz="0.1368 0.01 0" rpy="${M_PI} 0 ${M_PI/4}" />
      <parent link="${name}_base_link" />
      <child link="${name}_link5" />
      <axis xyz="0 0 -1" />
      <limit lower="-6.28" upper="6.28" velocity="2.0" effort="50" /> <!-- Fake effort and velocity
      for
      gripper -->
    </joint>

    <link name="${name}_link6">
      <inertial>
        <origin xyz="0.010320000000000001 0.00034 -0.0" rpy="0 0 0" />
        <mass value="0.026000000000000002" />
        <inertia ixx="1.57e-06" ixy="-1.92e-06" ixz="0.0" iyy="1.1380000000000001e-05" iyz="0.0"
          izz="1.176e-05" />
      </inertial>
      <visual>
        <origin xyz="0 0 0" rpy="0 0 0" />
        <geometry>
          <mesh
            filename="package://galbot_one_golf_description/meshes/visual/gripper/hitbot_gripper/gripper_link6/obj/gripper_link6.obj" />
        </geometry>
      </visual>
      <xacro:if value="${collision_type == 'sphere'}">
        <collision>
          <origin xyz="0 0 0" rpy="0 0 0" />
          <geometry>
            <sphere radius="0.05" />
          </geometry>
        </collision>
      </xacro:if>
      <xacro:if value="${collision_type == 'mesh'}">
        <collision>
          <origin xyz="0 0 0" rpy="0 0 0" />
          <geometry>
            <mesh
              filename="package://galbot_one_golf_description/meshes/collision/gripper/hitbot_gripper/gripper_link6/original/gripper_link6.stl" />
          </geometry>
        </collision>
      </xacro:if>
      <xacro:if value="${collision_type == 'convex_hull'}">
        <collision>
          <origin xyz="0 0 0" rpy="0 0 0" />
          <geometry>
            <mesh
              filename="package://galbot_one_golf_description/meshes/collision/gripper/hitbot_gripper/gripper_link6/convex_hull/gripper_link6_convex_hull.stl" />
          </geometry>
        </collision>
      </xacro:if>
      <xacro:if value="${collision_type == 'convex_decomposition'}">
        <collision>
          <origin xyz="0 0 0" rpy="0 0 0" />
          <geometry>
            <mesh
              filename="package://galbot_one_golf_description/meshes/collision/gripper/hitbot_gripper/gripper_link6/convex_decomposition/gripper_link6_convex_decomposition_0.stl" />
          </geometry>
        </collision>
        <collision>
          <origin xyz="0 0 0" rpy="0 0 0" />
          <geometry>
            <mesh
              filename="package://galbot_one_golf_description/meshes/collision/gripper/hitbot_gripper/gripper_link6/convex_decomposition/gripper_link6_convex_decomposition_1.stl" />
          </geometry>
        </collision>
      </xacro:if>
    </link>

    <joint name="${name}_joint6" type="revolute">
      <origin xyz="0.065 0 0" rpy="0 0 ${M_PI/4}" />
      <parent link="${name}_link5" />
      <child link="${name}_link6" />
      <axis xyz="0 0 -1" />
      <limit lower="-6.28" upper="6.28" velocity="2.0" effort="50" /> <!-- Fake effort and velocity
      for
      gripper -->
    </joint>

    <!-- Tool Center Point -->
    <link name="${name}_tcp_link" />
    <joint name="${name}_tcp_joint" type="fixed">
      <origin xyz="0.222892 0 0 " rpy="0 0 0" />
      <parent link="${name}_base_link" />
      <child link="${name}_tcp_link" />
      <axis xyz="0 0 0" />
    </joint>

  </xacro:macro>
</robot>