<?xml version='1.0' encoding='UTF-8'?>
<!-- 
#####################################################################################
#
# Copyright (c) 2023-2025 Galbot, Inc. All Rights Reserved.
#
# This software contains confidential and proprietary information of Galbot, Inc.
# ("Confidential Information"). You shall not disclose such Confidential Information
# and shall use it only in accordance with the terms of the license agreement you
# entered into with Galbot, Inc.
#
# UNAUTHORIZED COPYING, USE, OR DISTRIBUTION OF THIS SOFTWARE, OR ANY PORTION OR
# DERIVATIVE THEREOF, IS STRICTLY PROHIBITED. IF YOU HAVE RECEIVED THIS SOFTWARE IN
# ERROR, PLEASE NOTIFY GALBOT, INC. IMMEDIATELY AND DELETE IT FROM YOUR SYSTEM.
#
#####################################################################################
#
# Description: XACRO file for galbot_one_golf leg.
# Maintainer: Herman Ye, Yuhao Zeng@Galbot
#
#####################################################################################
-->
<robot xmlns:xacro="http://ros.org/wiki/xacro" name="leg">

  <xacro:macro name="leg" params="parent *origin name:=leg collision_type:=convex_decomposition">
    <xacro:property name="M_PI" value="3.1415926535897931" />

    <joint name="${name}_joint" type="fixed">
      <xacro:insert_block name="origin" />
      <parent link="${parent}" />
      <child link="${name}_base_link" />
    </joint>

    <link name="${name}_base_link">
      <inertial>
        <origin xyz="7.000000000000001e-05 -0.05414 0.0" rpy="0 0 0" />
        <mass value="1.58" />
        <inertia ixx="0.00797474" ixy="8.35e-06" ixz="2e-08" iyy="0.00248067" iyz="6.9e-07"
          izz="0.00797203" />
      </inertial>
    </link>

    <link name="${name}_link1">
      <inertial>
        <origin xyz="0.21883000000000002 0.00219 -0.0046" rpy="0 0 0" />
        <mass value="5.28" />
        <inertia ixx="0.0245158" ixy="0.003598" ixz="-0.004119" iyy="0.46437793" iyz="2.301e-05"
          izz="0.46079615" />
      </inertial>
      <visual>
        <origin xyz="0 0 0" rpy="0 0 0" />
        <geometry>
          <mesh
            filename="package://galbot_one_golf_description/meshes/visual/leg/leg_link1/obj/leg_link1.obj" />
        </geometry>
      </visual>
      <xacro:if value="${collision_type == 'sphere'}">
        <collision>
          <origin xyz="0.0 0.0 0.0" rpy="0 0 0" /> <!-- center: [0.0, 0.0, 0.0] -->
          <geometry>
            <sphere radius="0.095" />
          </geometry>
        </collision>
        <collision>
          <origin xyz="0.1 -0.03 0.0" rpy="0 0 0" /> <!-- center: [0.1, -0.03, 0.0] -->
          <geometry>
            <sphere radius="0.095" />
          </geometry>
        </collision>
        <collision>
          <origin xyz="0.22 -0.03 0.0" rpy="0 0 0" /> <!-- center: [0.22, -0.03, 0.0] -->
          <geometry>
            <sphere radius="0.095" />
          </geometry>
        </collision>
        <collision>
          <origin xyz="0.33 -0.03 0.0" rpy="0 0 0" /> <!-- center: [0.33, -0.03, 0.0] -->
          <geometry>
            <sphere radius="0.095" />
          </geometry>
        </collision>
      </xacro:if>
      <xacro:if value="${collision_type == 'mesh'}">
        <collision>
          <origin xyz="0 0 0" rpy="0 0 0" />
          <geometry>
            <mesh
              filename="package://galbot_one_golf_description/meshes/collision/leg/leg_link1/original/leg_link1.stl" />
          </geometry>
        </collision>
      </xacro:if>
      <xacro:if value="${collision_type == 'convex_hull'}">
        <collision>
          <origin xyz="0 0 0" rpy="0 0 0" />
          <geometry>
            <mesh
              filename="package://galbot_one_golf_description/meshes/collision/leg/leg_link1/convex_hull/leg_link1_convex_hull.stl" />
          </geometry>
        </collision>
      </xacro:if>
      <xacro:if value="${collision_type == 'convex_decomposition'}">
        <collision>
          <origin xyz="0 0 0" rpy="0 0 0" />
          <geometry>
            <mesh
              filename="package://galbot_one_golf_description/meshes/collision/leg/leg_link1/convex_decomposition/leg_link1_convex_decomposition_0.stl" />
          </geometry>
        </collision>
        <collision>
          <origin xyz="0 0 0" rpy="0 0 0" />
          <geometry>
            <mesh
              filename="package://galbot_one_golf_description/meshes/collision/leg/leg_link1/convex_decomposition/leg_link1_convex_decomposition_1.stl" />
          </geometry>
        </collision>
        <collision>
          <origin xyz="0 0 0" rpy="0 0 0" />
          <geometry>
            <mesh
              filename="package://galbot_one_golf_description/meshes/collision/leg/leg_link1/convex_decomposition/leg_link1_convex_decomposition_2.stl" />
          </geometry>
        </collision>
        <collision>
          <origin xyz="0 0 0" rpy="0 0 0" />
          <geometry>
            <mesh
              filename="package://galbot_one_golf_description/meshes/collision/leg/leg_link1/convex_decomposition/leg_link1_convex_decomposition_3.stl" />
          </geometry>
        </collision>
      </xacro:if>
    </link>
    <joint name="${name}_joint1" type="revolute">
      <origin xyz="0 0 0" rpy="${M_PI/2} -0.385 ${M_PI}" />
      <parent link="${name}_base_link" />
      <child link="${name}_link1" />
      <axis xyz="0 0 1" />
      <limit lower="0.0" upper="0.9374" effort="169" velocity="1" />
    </joint>

    <link name="${name}_link2">
      <inertial>
        <origin xyz="0.19484 0.0 0.0" rpy="0 0 0" />
        <mass value="3.3" />
        <inertia ixx="0.04156241" ixy="7.2e-07" ixz="1.559e-05" iyy="0.23231617000000002"
          iyz="-2.7799999999999996e-06" izz="0.20323657" />
      </inertial>
      <visual>
        <origin xyz="0 0 0" rpy="0 0 0" />
        <geometry>
          <mesh
            filename="package://galbot_one_golf_description/meshes/visual/leg/leg_link2/obj/leg_link2.obj" />
        </geometry>
      </visual>
      <xacro:if value="${collision_type == 'sphere'}">
        <collision>
          <origin xyz="0.0 0.0 0.0" rpy="0 0 0" />
          <geometry>
            <sphere radius="0.085" />
          </geometry>
        </collision>
        <collision>
          <origin xyz="0.0 0.0 0.06" rpy="0 0 0" />
          <geometry>
            <sphere radius="0.085" />
          </geometry>
        </collision>
        <collision>
          <origin xyz="0.0 0.0 -0.06" rpy="0 0 0" />
          <geometry>
            <sphere radius="0.085" />
          </geometry>
        </collision>
        <collision>
          <origin xyz="0.05 0.0 0.06" rpy="0 0 0" />
          <geometry>
            <sphere radius="0.085" />
          </geometry>
        </collision>
        <collision>
          <origin xyz="0.05 0.0 -0.06" rpy="0 0 0" />
          <geometry>
            <sphere radius="0.085" />
          </geometry>
        </collision>
        <collision>
          <origin xyz="0.1 0.0 0.06" rpy="0 0 0" />
          <geometry>
            <sphere radius="0.085" />
          </geometry>
        </collision>
        <collision>
          <origin xyz="0.1 0.0 -0.06" rpy="0 0 0" />
          <geometry>
            <sphere radius="0.085" />
          </geometry>
        </collision>
        <collision>
          <origin xyz="0.15 0.0 0.06" rpy="0 0 0" />
          <geometry>
            <sphere radius="0.085" />
          </geometry>
        </collision>
        <collision>
          <origin xyz="0.15 0.0 -0.06" rpy="0 0 0" />
          <geometry>
            <sphere radius="0.085" />
          </geometry>
        </collision>
        <collision>
          <origin xyz="0.2 0.0 0.06" rpy="0 0 0" />
          <geometry>
            <sphere radius="0.085" />
          </geometry>
        </collision>
        <collision>
          <origin xyz="0.2 0.0 -0.06" rpy="0 0 0" />
          <geometry>
            <sphere radius="0.085" />
          </geometry>
        </collision>
        <collision>
          <origin xyz="0.25 0.0 0.06" rpy="0 0 0" />
          <geometry>
            <sphere radius="0.085" />
          </geometry>
        </collision>
        <collision>
          <origin xyz="0.25 0.0 -0.06" rpy="0 0 0" />
          <geometry>
            <sphere radius="0.085" />
          </geometry>
        </collision>
        <collision>
          <origin xyz="0.3 0.0 0.06" rpy="0 0 0" />
          <geometry>
            <sphere radius="0.085" />
          </geometry>
        </collision>
        <collision>
          <origin xyz="0.3 0.0 -0.06" rpy="0 0 0" />
          <geometry>
            <sphere radius="0.085" />
          </geometry>
        </collision>
        <collision>
          <origin xyz="0.35 0.0 0.06" rpy="0 0 0" />
          <geometry>
            <sphere radius="0.085" />
          </geometry>
        </collision>
        <collision>
          <origin xyz="0.35 0.0 -0.06" rpy="0 0 0" />
          <geometry>
            <sphere radius="0.085" />
          </geometry>
        </collision>
        <collision>
          <origin xyz="0.4 0.0 0.06" rpy="0 0 0" />
          <geometry>
            <sphere radius="0.085" />
          </geometry>
        </collision>
        <collision>
          <origin xyz="0.4 0.0 -0.06" rpy="0 0 0" />
          <geometry>
            <sphere radius="0.085" />
          </geometry>
        </collision>
        <collision>
          <origin xyz="0.4 0.0 0.0" rpy="0 0 0" />
          <geometry>
            <sphere radius="0.085" />
          </geometry>
        </collision>
      </xacro:if>
      <xacro:if value="${collision_type == 'mesh'}">
        <collision>
          <origin xyz="0 0 0" rpy="0 0 0" />
          <geometry>
            <mesh
              filename="package://galbot_one_golf_description/meshes/collision/leg/leg_link2/original/leg_link2.stl" />
          </geometry>
        </collision>
      </xacro:if>
      <xacro:if value="${collision_type == 'convex_hull'}">
        <collision>
          <origin xyz="0 0 0" rpy="0 0 0" />
          <geometry>
            <mesh
              filename="package://galbot_one_golf_description/meshes/collision/leg/leg_link2/convex_hull/leg_link2_convex_hull.stl" />
          </geometry>
        </collision>
      </xacro:if>
      <xacro:if value="${collision_type == 'convex_decomposition'}">
        <collision>
          <origin xyz="0 0 0" rpy="0 0 0" />
          <geometry>
            <mesh
              filename="package://galbot_one_golf_description/meshes/collision/leg/leg_link2/convex_decomposition/leg_link2_convex_decomposition_0.stl" />
          </geometry>
        </collision>
        <collision>
          <origin xyz="0 0 0" rpy="0 0 0" />
          <geometry>
            <mesh
              filename="package://galbot_one_golf_description/meshes/collision/leg/leg_link2/convex_decomposition/leg_link2_convex_decomposition_1.stl" />
          </geometry>
        </collision>
      </xacro:if>
    </link>
    <joint name="${name}_joint2" type="revolute">
      <origin xyz="0.45 0 0" rpy="${M_PI} 0 2.7566" />
      <parent link="${name}_link1" />
      <child link="${name}_link2" />
      <axis xyz="0 0 1" />
      <limit lower="0.0" upper="2.5847" effort="169" velocity="1" />
    </joint>

    <link name="${name}_link3">
      <inertial>
        <origin xyz="2e-05 0.01881 -0.011" rpy="0 0 0" />
        <mass value="1.76" />
        <inertia ixx="0.01102444" ixy="1.13e-06" ixz="-1.26e-06" iyy="0.00878281" iyz="1.26e-06"
          izz="0.0106222" />
      </inertial>
      <visual>
        <origin xyz="0 0 0" rpy="0 0 0" />
        <geometry>
          <mesh
            filename="package://galbot_one_golf_description/meshes/visual/leg/leg_link3/obj/leg_link3.obj" />
        </geometry>
      </visual>
      <xacro:if value="${collision_type == 'sphere'}">
        <collision>
          <origin xyz="0 0 0" rpy="0 0 0" />
          <geometry>
            <sphere radius="0.1" />
          </geometry>
        </collision>
      </xacro:if>
      <xacro:if value="${collision_type == 'mesh'}">
        <collision>
          <origin xyz="0 0 0" rpy="0 0 0" />
          <geometry>
            <mesh
              filename="package://galbot_one_golf_description/meshes/collision/leg/leg_link3/original/leg_link3.stl" />
          </geometry>
        </collision>
      </xacro:if>
      <xacro:if value="${collision_type == 'convex_hull'}">
        <collision>
          <origin xyz="0 0 0" rpy="0 0 0" />
          <geometry>
            <mesh
              filename="package://galbot_one_golf_description/meshes/collision/leg/leg_link3/convex_hull/leg_link3_convex_hull.stl" />
          </geometry>
        </collision>
      </xacro:if>
      <xacro:if value="${collision_type == 'convex_decomposition'}">
        <collision>
          <origin xyz="0 0 0" rpy="0 0 0" />
          <geometry>
            <mesh
              filename="package://galbot_one_golf_description/meshes/collision/leg/leg_link3/convex_decomposition/leg_link3_convex_decomposition_0.stl" />
          </geometry>
        </collision>
        <collision>
          <origin xyz="0 0 0" rpy="0 0 0" />
          <geometry>
            <mesh
              filename="package://galbot_one_golf_description/meshes/collision/leg/leg_link3/convex_decomposition/leg_link3_convex_decomposition_1.stl" />
          </geometry>
        </collision>
        <collision>
          <origin xyz="0 0 0" rpy="0 0 0" />
          <geometry>
            <mesh
              filename="package://galbot_one_golf_description/meshes/collision/leg/leg_link3/convex_decomposition/leg_link3_convex_decomposition_2.stl" />
          </geometry>
        </collision>
        <collision>
          <origin xyz="0 0 0" rpy="0 0 0" />
          <geometry>
            <mesh
              filename="package://galbot_one_golf_description/meshes/collision/leg/leg_link3/convex_decomposition/leg_link3_convex_decomposition_3.stl" />
          </geometry>
        </collision>
        <collision>
          <origin xyz="0 0 0" rpy="0 0 0" />
          <geometry>
            <mesh
              filename="package://galbot_one_golf_description/meshes/collision/leg/leg_link3/convex_decomposition/leg_link3_convex_decomposition_4.stl" />
          </geometry>
        </collision>
        <collision>
          <origin xyz="0 0 0" rpy="0 0 0" />
          <geometry>
            <mesh
              filename="package://galbot_one_golf_description/meshes/collision/leg/leg_link3/convex_decomposition/leg_link3_convex_decomposition_5.stl" />
          </geometry>
        </collision>
        <collision>
          <origin xyz="0 0 0" rpy="0 0 0" />
          <geometry>
            <mesh
              filename="package://galbot_one_golf_description/meshes/collision/leg/leg_link3/convex_decomposition/leg_link3_convex_decomposition_6.stl" />
          </geometry>
        </collision>
        <collision>
          <origin xyz="0 0 0" rpy="0 0 0" />
          <geometry>
            <mesh
              filename="package://galbot_one_golf_description/meshes/collision/leg/leg_link3/convex_decomposition/leg_link3_convex_decomposition_7.stl" />
          </geometry>
        </collision>
        <collision>
          <origin xyz="0 0 0" rpy="0 0 0" />
          <geometry>
            <mesh
              filename="package://galbot_one_golf_description/meshes/collision/leg/leg_link3/convex_decomposition/leg_link3_convex_decomposition_8.stl" />
          </geometry>
        </collision>
        <collision>
          <origin xyz="0 0 0" rpy="0 0 0" />
          <geometry>
            <mesh
              filename="package://galbot_one_golf_description/meshes/collision/leg/leg_link3/convex_decomposition/leg_link3_convex_decomposition_9.stl" />
          </geometry>
        </collision>
        <collision>
          <origin xyz="0 0 0" rpy="0 0 0" />
          <geometry>
            <mesh
              filename="package://galbot_one_golf_description/meshes/collision/leg/leg_link3/convex_decomposition/leg_link3_convex_decomposition_10.stl" />
          </geometry>
        </collision>
        <collision>
          <origin xyz="0 0 0" rpy="0 0 0" />
          <geometry>
            <mesh
              filename="package://galbot_one_golf_description/meshes/collision/leg/leg_link3/convex_decomposition/leg_link3_convex_decomposition_11.stl" />
          </geometry>
        </collision>
        <collision>
          <origin xyz="0 0 0" rpy="0 0 0" />
          <geometry>
            <mesh
              filename="package://galbot_one_golf_description/meshes/collision/leg/leg_link3/convex_decomposition/leg_link3_convex_decomposition_12.stl" />
          </geometry>
        </collision>
        <collision>
          <origin xyz="0 0 0" rpy="0 0 0" />
          <geometry>
            <mesh
              filename="package://galbot_one_golf_description/meshes/collision/leg/leg_link3/convex_decomposition/leg_link3_convex_decomposition_13.stl" />
          </geometry>
        </collision>
        <collision>
          <origin xyz="0 0 0" rpy="0 0 0" />
          <geometry>
            <mesh
              filename="package://galbot_one_golf_description/meshes/collision/leg/leg_link3/convex_decomposition/leg_link3_convex_decomposition_14.stl" />
          </geometry>
        </collision>
        <collision>
          <origin xyz="0 0 0" rpy="0 0 0" />
          <geometry>
            <mesh
              filename="package://galbot_one_golf_description/meshes/collision/leg/leg_link3/convex_decomposition/leg_link3_convex_decomposition_15.stl" />
          </geometry>
        </collision>
      </xacro:if>
    </link>
    <joint name="${name}_joint3" type="revolute">
      <origin xyz="0.39 0 0" rpy="${M_PI} 0 ${M_PI}" />
      <parent link="${name}_link2" />
      <child link="${name}_link3" />
      <axis xyz="0 0 1" />
      <limit lower="0.0" upper="2.3262" effort="84" velocity="1" />
    </joint>

    <link name="${name}_link4">
      <inertial>
        <origin xyz="0.0 -0.0059900000000000005 -0.06877" rpy="0 0 0" />
        <mass value="0.72" />
        <inertia ixx="0.00580757" ixy="0.0" ixz="0.0" iyy="0.00591483" iyz="4.67e-06"
          izz="0.0014004900000000001" />
      </inertial>
      <visual>
        <origin xyz="0 0 0" rpy="0 0 0" />
        <geometry>
          <mesh
            filename="package://galbot_one_golf_description/meshes/visual/leg/leg_link4/obj/leg_link4.obj" />
        </geometry>
      </visual>
      <xacro:if value="${collision_type == 'sphere'}">
        <collision>
          <origin xyz="0 0 0" rpy="0 0 0" />
          <geometry>
            <sphere radius="0.1" />
          </geometry>
        </collision>
      </xacro:if>
      <xacro:if value="${collision_type == 'mesh'}">
        <collision>
          <origin xyz="0 0 0" rpy="0 0 0" />
          <geometry>
            <mesh
              filename="package://galbot_one_golf_description/meshes/collision/leg/leg_link4/original/leg_link4.stl" />
          </geometry>
        </collision>
      </xacro:if>
      <xacro:if value="${collision_type == 'convex_hull'}">
        <collision>
          <origin xyz="0 0 0" rpy="0 0 0" />
          <geometry>
            <mesh
              filename="package://galbot_one_golf_description/meshes/collision/leg/leg_link4/convex_hull/leg_link4_convex_hull.stl" />
          </geometry>
        </collision>
      </xacro:if>
      <xacro:if value="${collision_type == 'convex_decomposition'}">
        <collision>
          <origin xyz="0 0 0" rpy="0 0 0" />
          <geometry>
            <mesh
              filename="package://galbot_one_golf_description/meshes/collision/leg/leg_link4/convex_decomposition/leg_link4_convex_decomposition_0.stl" />
          </geometry>
        </collision>
        <collision>
          <origin xyz="0 0 0" rpy="0 0 0" />
          <geometry>
            <mesh
              filename="package://galbot_one_golf_description/meshes/collision/leg/leg_link4/convex_decomposition/leg_link4_convex_decomposition_1.stl" />
          </geometry>
        </collision>
        <collision>
          <origin xyz="0 0 0" rpy="0 0 0" />
          <geometry>
            <mesh
              filename="package://galbot_one_golf_description/meshes/collision/leg/leg_link4/convex_decomposition/leg_link4_convex_decomposition_2.stl" />
          </geometry>
        </collision>
        <collision>
          <origin xyz="0 0 0" rpy="0 0 0" />
          <geometry>
            <mesh
              filename="package://galbot_one_golf_description/meshes/collision/leg/leg_link4/convex_decomposition/leg_link4_convex_decomposition_3.stl" />
          </geometry>
        </collision>
        <collision>
          <origin xyz="0 0 0" rpy="0 0 0" />
          <geometry>
            <mesh
              filename="package://galbot_one_golf_description/meshes/collision/leg/leg_link4/convex_decomposition/leg_link4_convex_decomposition_4.stl" />
          </geometry>
        </collision>
        <collision>
          <origin xyz="0 0 0" rpy="0 0 0" />
          <geometry>
            <mesh
              filename="package://galbot_one_golf_description/meshes/collision/leg/leg_link4/convex_decomposition/leg_link4_convex_decomposition_5.stl" />
          </geometry>
        </collision>
        <collision>
          <origin xyz="0 0 0" rpy="0 0 0" />
          <geometry>
            <mesh
              filename="package://galbot_one_golf_description/meshes/collision/leg/leg_link4/convex_decomposition/leg_link4_convex_decomposition_6.stl" />
          </geometry>
        </collision>
        <collision>
          <origin xyz="0 0 0" rpy="0 0 0" />
          <geometry>
            <mesh
              filename="package://galbot_one_golf_description/meshes/collision/leg/leg_link4/convex_decomposition/leg_link4_convex_decomposition_7.stl" />
          </geometry>
        </collision>
        <collision>
          <origin xyz="0 0 0" rpy="0 0 0" />
          <geometry>
            <mesh
              filename="package://galbot_one_golf_description/meshes/collision/leg/leg_link4/convex_decomposition/leg_link4_convex_decomposition_8.stl" />
          </geometry>
        </collision>
        <collision>
          <origin xyz="0 0 0" rpy="0 0 0" />
          <geometry>
            <mesh
              filename="package://galbot_one_golf_description/meshes/collision/leg/leg_link4/convex_decomposition/leg_link4_convex_decomposition_9.stl" />
          </geometry>
        </collision>
      </xacro:if>
    </link>
    <joint name="${name}_joint4" type="revolute">
      <origin xyz="0 0.224 0" rpy="${-M_PI/2} ${-M_PI/2} 0" />
      <parent link="${name}_link3" />
      <child link="${name}_link4" />
      <axis xyz="0 0 1" />
      <limit lower="-1.5906" upper="1.5906" effort="30" velocity="1" />
    </joint>

    <link name="${name}_link5">
      <inertial>
        <origin xyz="0.0 0.032369999999999996 0.03006" rpy="0 0 0" />
        <mass value="0.41" />
        <inertia ixx="0.00142201" ixy="0.0" ixz="0.0" iyy="0.00132398" iyz="0.00023940999999999999"
          izz="0.00156199" />
      </inertial>
      <visual>
        <origin xyz="0 0 0" rpy="0 0 0" />
        <geometry>
          <mesh
            filename="package://galbot_one_golf_description/meshes/visual/leg/leg_link5/obj/leg_link5.obj" />
        </geometry>
      </visual>
      <xacro:if value="${collision_type == 'sphere'}">
        <!-- <collision>
          <origin xyz="0 0 0" rpy="0 0 0" />
          <geometry>
            <sphere radius="0.1" />
          </geometry>
        </collision> -->
      </xacro:if>
      <xacro:if value="${collision_type == 'mesh'}">
        <collision>
          <origin xyz="0 0 0" rpy="0 0 0" />
          <geometry>
            <mesh
              filename="package://galbot_one_golf_description/meshes/collision/leg/leg_link5/original/leg_link5.stl" />
          </geometry>
        </collision>
      </xacro:if>
      <xacro:if value="${collision_type == 'convex_hull'}">
        <collision>
          <origin xyz="0 0 0" rpy="0 0 0" />
          <geometry>
            <mesh
              filename="package://galbot_one_golf_description/meshes/collision/leg/leg_link5/convex_hull/leg_link5_convex_hull.stl" />
          </geometry>
        </collision>
      </xacro:if>
      <xacro:if value="${collision_type == 'convex_decomposition'}">
        <collision>
          <origin xyz="0 0 0" rpy="0 0 0" />
          <geometry>
            <mesh
              filename="package://galbot_one_golf_description/meshes/collision/leg/leg_link5/convex_decomposition/leg_link5_convex_decomposition_0.stl" />
          </geometry>
        </collision>
        <collision>
          <origin xyz="0 0 0" rpy="0 0 0" />
          <geometry>
            <mesh
              filename="package://galbot_one_golf_description/meshes/collision/leg/leg_link5/convex_decomposition/leg_link5_convex_decomposition_1.stl" />
          </geometry>
        </collision>
        <collision>
          <origin xyz="0 0 0" rpy="0 0 0" />
          <geometry>
            <mesh
              filename="package://galbot_one_golf_description/meshes/collision/leg/leg_link5/convex_decomposition/leg_link5_convex_decomposition_2.stl" />
          </geometry>
        </collision>
        <collision>
          <origin xyz="0 0 0" rpy="0 0 0" />
          <geometry>
            <mesh
              filename="package://galbot_one_golf_description/meshes/collision/leg/leg_link5/convex_decomposition/leg_link5_convex_decomposition_3.stl" />
          </geometry>
        </collision>
        <collision>
          <origin xyz="0 0 0" rpy="0 0 0" />
          <geometry>
            <mesh
              filename="package://galbot_one_golf_description/meshes/collision/leg/leg_link5/convex_decomposition/leg_link5_convex_decomposition_4.stl" />
          </geometry>
        </collision>
        <collision>
          <origin xyz="0 0 0" rpy="0 0 0" />
          <geometry>
            <mesh
              filename="package://galbot_one_golf_description/meshes/collision/leg/leg_link5/convex_decomposition/leg_link5_convex_decomposition_5.stl" />
          </geometry>
        </collision>
        <collision>
          <origin xyz="0 0 0" rpy="0 0 0" />
          <geometry>
            <mesh
              filename="package://galbot_one_golf_description/meshes/collision/leg/leg_link5/convex_decomposition/leg_link5_convex_decomposition_6.stl" />
          </geometry>
        </collision>
        <collision>
          <origin xyz="0 0 0" rpy="0 0 0" />
          <geometry>
            <mesh
              filename="package://galbot_one_golf_description/meshes/collision/leg/leg_link5/convex_decomposition/leg_link5_convex_decomposition_7.stl" />
          </geometry>
        </collision>
        <collision>
          <origin xyz="0 0 0" rpy="0 0 0" />
          <geometry>
            <mesh
              filename="package://galbot_one_golf_description/meshes/collision/leg/leg_link5/convex_decomposition/leg_link5_convex_decomposition_8.stl" />
          </geometry>
        </collision>
        <collision>
          <origin xyz="0 0 0" rpy="0 0 0" />
          <geometry>
            <mesh
              filename="package://galbot_one_golf_description/meshes/collision/leg/leg_link5/convex_decomposition/leg_link5_convex_decomposition_9.stl" />
          </geometry>
        </collision>
        <collision>
          <origin xyz="0 0 0" rpy="0 0 0" />
          <geometry>
            <mesh
              filename="package://galbot_one_golf_description/meshes/collision/leg/leg_link5/convex_decomposition/leg_link5_convex_decomposition_10.stl" />
          </geometry>
        </collision>
        <collision>
          <origin xyz="0 0 0" rpy="0 0 0" />
          <geometry>
            <mesh
              filename="package://galbot_one_golf_description/meshes/collision/leg/leg_link5/convex_decomposition/leg_link5_convex_decomposition_11.stl" />
          </geometry>
        </collision>
      </xacro:if>
    </link>
    <joint name="${name}_joint5" type="revolute">
      <origin xyz="0 0 0" rpy="${M_PI/2} 0 0" />
      <parent link="${name}_link4" />
      <child link="${name}_link5" />
      <axis xyz="0 0 1" />
      <limit lower="-0.1645" upper="0.1645" effort="30" velocity="1" />  <!-- special soft limit for
      leg joint 5 (0.01 radians)-->
    </joint>

    <link name="${name}_end_effector_mount_link">
      <inertial>
        <origin xyz="0 0 0" rpy="0 0 0" />
        <mass value="0" />
        <inertia ixx="0" ixy="0" ixz="0" iyy="0" iyz="0" izz="0" />
      </inertial>
    </link>
    <joint name="${name}_end_effector_mount_joint" type="fixed">
      <origin xyz="0 0 0" rpy="0 0 0" />
      <parent link="${name}_link5" />
      <child link="${name}_end_effector_mount_link" />
      <axis xyz="0 0 0" />
    </joint>


  </xacro:macro>
</robot>