<?xml version="1.0" ?>
<robot name="galbot_g1_v2_2_1">
  <link name="base_link">
    </link>
  <joint name="omni_chassis_joint" type="fixed">
    <origin rpy="0.0 0.0 0.0" xyz="0.0 0.0 0.0"/>
    <parent link="base_link"/>
    <child link="omni_chassis_base_link"/>
  </joint>
  <link name="omni_chassis_base_link">
    <visual>
      <origin rpy="0 0 0" xyz="0 0 0"/>
      <geometry>
        <mesh filename="package://galbot_g1_description/meshes/v2_2_1/visual/high/omni_chassis_base_link.obj"/>
      </geometry>
    </visual>
    <inertial>
      <origin rpy="0.0 0.0 0.0" xyz="0.02644 -0.00449 0.07524"/>
      <mass value="8.04"/>
      <inertia ixx="0.19508898000000002" ixy="0.00306854" ixz="0.01503967" iyy="0.29573702" iyz="-0.00295148" izz="0.3313144"/>
    </inertial>
    <collision>
      <origin rpy="0 0 0" xyz="0 0 0"/>
      <geometry>
        <mesh filename="package://galbot_g1_description/meshes/v2_2_1/collision/convex_hull/omni_chassis_base_link.stl"/>
      </geometry>
    </collision>
  </link>
  <link name="omni_chassis_leg_mount_link">
    <inertial>
      <origin rpy="0.0 0.0 0.0" xyz="0.0 0.0 0.0"/>
      <mass value="0.0"/>
      <inertia ixx="0.0" ixy="0.0" ixz="0.0" iyy="0.0" iyz="0.0" izz="0.0"/>
    </inertial>
  </link>
  <joint name="omni_chassis_leg_mount_joint" type="fixed">
    <origin rpy="0.0 0.0 0.0" xyz="0.134 0.0 0.1325"/>
    <parent link="omni_chassis_base_link"/>
    <child link="omni_chassis_leg_mount_link"/>
  </joint>
  <joint name="leg_base_joint" type="fixed">
    <origin rpy="0.0 0.0 0.0" xyz="0.0 0.0 0.0"/>
    <parent link="omni_chassis_leg_mount_link"/>
    <child link="leg_base_link"/>
  </joint>
  <link name="leg_base_link">
    <inertial>
      <origin rpy="0.0 0.0 0.0" xyz="7.000000000000001e-05 -0.05414 0.0"/>
      <mass value="1.58"/>
      <inertia ixx="0.00797474" ixy="8.35e-06" ixz="2e-08" iyy="0.00248067" iyz="6.9e-07" izz="0.00797203"/>
    </inertial>
  </link>
  <link name="leg_link1">
    <visual>
      <origin rpy="0 0 0" xyz="0 0 0"/>
      <geometry>
        <mesh filename="package://galbot_g1_description/meshes/v2_2_1/visual/high/leg_link1.obj"/>
      </geometry>
    </visual>
    <inertial>
      <origin rpy="0.0 0.0 0.0" xyz="0.21883000000000002 0.00219 -0.0046"/>
      <mass value="5.28"/>
      <inertia ixx="0.0245158" ixy="0.003598" ixz="-0.004119" iyy="0.46437793" iyz="2.301e-05" izz="0.46079615"/>
    </inertial>
    <collision>
      <origin rpy="0 0 0" xyz="0 0 0"/>
      <geometry>
        <mesh filename="package://galbot_g1_description/meshes/v2_2_1/collision/convex_hull/leg_link1.stl"/>
      </geometry>
    </collision>
  </link>
  <joint name="leg_joint1" type="revolute">
    <origin rpy="1.5707963267948966 -0.385 3.141592653589793" xyz="0.0 0.0 0.0"/>
    <parent link="leg_base_link"/>
    <child link="leg_link1"/>
    <axis xyz="0.0 0.0 1.0"/>
    <limit effort="169.0" lower="0.0" upper="0.9374" velocity="1.0"/>
  </joint>
  <link name="leg_link2">
    <visual>
      <origin rpy="0 0 0" xyz="0 0 0"/>
      <geometry>
        <mesh filename="package://galbot_g1_description/meshes/v2_2_1/visual/high/leg_link2.obj"/>
      </geometry>
    </visual>
    <inertial>
      <origin rpy="0.0 0.0 0.0" xyz="0.19484 0.0 0.0"/>
      <mass value="3.3"/>
      <inertia ixx="0.04156241" ixy="7.2e-07" ixz="1.559e-05" iyy="0.23231617000000002" iyz="-2.7799999999999996e-06" izz="0.20323657"/>
    </inertial>
    <collision>
      <origin rpy="0 0 0" xyz="0 0 0"/>
      <geometry>
        <mesh filename="package://galbot_g1_description/meshes/v2_2_1/collision/convex_hull/leg_link2.stl"/>
      </geometry>
    </collision>
  </link>
  <joint name="leg_joint2" type="revolute">
    <origin rpy="3.141592653589793 0.0 2.7566" xyz="0.45 0.0 0.0"/>
    <parent link="leg_link1"/>
    <child link="leg_link2"/>
    <axis xyz="0.0 0.0 1.0"/>
    <limit effort="169.0" lower="0.0" upper="2.5847" velocity="1.0"/>
  </joint>
  <link name="leg_link3">
    <visual>
      <origin rpy="0 0 0" xyz="0 0 0"/>
      <geometry>
        <mesh filename="package://galbot_g1_description/meshes/v2_2_1/visual/high/leg_link3.obj"/>
      </geometry>
    </visual>
    <inertial>
      <origin rpy="0.0 0.0 0.0" xyz="2e-05 0.01881 -0.011"/>
      <mass value="1.76"/>
      <inertia ixx="0.01102444" ixy="1.13e-06" ixz="-1.26e-06" iyy="0.00878281" iyz="1.26e-06" izz="0.0106222"/>
    </inertial>
    <collision>
      <origin rpy="0 0 0" xyz="0 0 0"/>
      <geometry>
        <mesh filename="package://galbot_g1_description/meshes/v2_2_1/collision/convex_hull/leg_link3.stl"/>
      </geometry>
    </collision>
  </link>
  <joint name="leg_joint3" type="revolute">
    <origin rpy="3.141592653589793 0.0 3.141592653589793" xyz="0.39 0.0 0.0"/>
    <parent link="leg_link2"/>
    <child link="leg_link3"/>
    <axis xyz="0.0 0.0 1.0"/>
    <limit effort="84.0" lower="0.0" upper="2.3262" velocity="1.0"/>
  </joint>
  <link name="leg_link4">
    <visual>
      <origin rpy="0 0 0" xyz="0 0 0"/>
      <geometry>
        <mesh filename="package://galbot_g1_description/meshes/v2_2_1/visual/high/leg_link4.obj"/>
      </geometry>
    </visual>
    <inertial>
      <origin rpy="0.0 0.0 0.0" xyz="0.0 -0.0059900000000000005 -0.06877"/>
      <mass value="0.72"/>
      <inertia ixx="0.00580757" ixy="0.0" ixz="0.0" iyy="0.00591483" iyz="4.67e-06" izz="0.0014004900000000001"/>
    </inertial>
    <collision>
      <origin rpy="0 0 0" xyz="0 0 0"/>
      <geometry>
        <mesh filename="package://galbot_g1_description/meshes/v2_2_1/collision/convex_hull/leg_link4.stl"/>
      </geometry>
    </collision>
  </link>
  <joint name="leg_joint4" type="revolute">
    <origin rpy="-1.5707963267948966 -1.5707963267948966 0.0" xyz="0.0 0.224 0.0"/>
    <parent link="leg_link3"/>
    <child link="leg_link4"/>
    <axis xyz="0.0 0.0 1.0"/>
    <limit effort="30.0" lower="-1.5906" upper="1.5906" velocity="1.0"/>
  </joint>
  <link name="leg_link5">
    <visual>
      <origin rpy="0 0 0" xyz="0 0 0"/>
      <geometry>
        <mesh filename="package://galbot_g1_description/meshes/v2_2_1/visual/high/leg_link5.obj"/>
      </geometry>
    </visual>
    <inertial>
      <origin rpy="0.0 0.0 0.0" xyz="0.0 0.032369999999999996 0.03006"/>
      <mass value="0.41"/>
      <inertia ixx="0.00142201" ixy="0.0" ixz="0.0" iyy="0.00132398" iyz="0.00023940999999999999" izz="0.00156199"/>
    </inertial>
    <collision>
      <origin rpy="0 0 0" xyz="0 0 0"/>
      <geometry>
        <mesh filename="package://galbot_g1_description/meshes/v2_2_1/collision/convex_hull/leg_link5.stl"/>
      </geometry>
    </collision>
  </link>
  <joint name="leg_joint5" type="revolute">
    <origin rpy="1.5707963267948966 0.0 0.0" xyz="0.0 0.0 0.0"/>
    <parent link="leg_link4"/>
    <child link="leg_link5"/>
    <axis xyz="0.0 0.0 1.0"/>
    <limit effort="30.0" lower="-0.1645" upper="0.1645" velocity="1.0"/>
  </joint>
  <link name="leg_end_effector_mount_link">
    <inertial>
      <origin rpy="0.0 0.0 0.0" xyz="0.0 0.0 0.0"/>
      <mass value="0.0"/>
      <inertia ixx="0.0" ixy="0.0" ixz="0.0" iyy="0.0" iyz="0.0" izz="0.0"/>
    </inertial>
  </link>
  <joint name="leg_end_effector_mount_joint" type="fixed">
    <origin rpy="0.0 0.0 0.0" xyz="0.0 0.0 0.0"/>
    <parent link="leg_link5"/>
    <child link="leg_end_effector_mount_link"/>
  </joint>
  <joint name="torso_base_joint" type="fixed">
    <origin rpy="0.0 0.0 0.0" xyz="0.0 0.0 0.0"/>
    <parent link="leg_end_effector_mount_link"/>
    <child link="torso_base_link"/>
  </joint>
  <link name="torso_base_link">
    <visual>
      <origin rpy="0 0 0" xyz="0 0 0"/>
      <geometry>
        <mesh filename="package://galbot_g1_description/meshes/v2_2_1/visual/high/torso_base_link.obj"/>
      </geometry>
    </visual>
    <inertial>
      <origin rpy="0.0 0.0 0.0" xyz="-4e-05 0.16976 -0.00174"/>
      <mass value="3.3"/>
      <inertia ixx="0.13068739999999998" ixy="-3.799e-05" ixz="2.6e-07" iyy="0.01888968" iyz="-0.00210909" izz="0.13964288"/>
    </inertial>
    <collision>
      <origin rpy="0 0 0" xyz="0 0 0"/>
      <geometry>
        <mesh filename="package://galbot_g1_description/meshes/v2_2_1/collision/convex_hull/torso_base_link.stl"/>
      </geometry>
    </collision>
  </link>
  <link name="torso_head_mount_link">
    <inertial>
      <origin rpy="0.0 0.0 0.0" xyz="0.0 0.0 0.0"/>
      <mass value="0.0"/>
      <inertia ixx="0.0" ixy="0.0" ixz="0.0" iyy="0.0" iyz="0.0" izz="0.0"/>
    </inertial>
  </link>
  <joint name="torso_head_mount_joint" type="fixed">
    <origin rpy="-1.5707963267948966 -1.5707963267948966 0.0" xyz="0.0 0.37711 0.0"/>
    <parent link="torso_base_link"/>
    <child link="torso_head_mount_link"/>
  </joint>
  <link name="torso_left_arm_mount_link">
    <inertial>
      <origin rpy="0.0 0.0 0.0" xyz="0.0 0.0 0.0"/>
      <mass value="0.0"/>
      <inertia ixx="0.0" ixy="0.0" ixz="0.0" iyy="0.0" iyz="0.0" izz="0.0"/>
    </inertial>
  </link>
  <joint name="torso_left_arm_mount_joint" type="fixed">
    <origin rpy="0.0 1.5707963267948966 0.0" xyz="0.20843 0.172 0.0"/>
    <parent link="torso_base_link"/>
    <child link="torso_left_arm_mount_link"/>
  </joint>
  <link name="torso_right_arm_mount_link">
    <inertial>
      <origin rpy="0.0 0.0 0.0" xyz="0.0 0.0 0.0"/>
      <mass value="0.0"/>
      <inertia ixx="0.0" ixy="0.0" ixz="0.0" iyy="0.0" iyz="0.0" izz="0.0"/>
    </inertial>
  </link>
  <joint name="torso_right_arm_mount_joint" type="fixed">
    <origin rpy="3.141592653589793 1.5707963267948966 0.0" xyz="-0.20843 0.172 0.0"/>
    <parent link="torso_base_link"/>
    <child link="torso_right_arm_mount_link"/>
  </joint>
  <joint name="head_base_joint" type="fixed">
    <origin rpy="0.0 0.0 0.0" xyz="0.0 0.0 0.0"/>
    <parent link="torso_head_mount_link"/>
    <child link="head_base_link"/>
  </joint>
  <link name="head_base_link">
    <inertial>
      <origin rpy="0.0 0.0 0.0" xyz="0.023809999999999998 0.00032 0.01966"/>
      <mass value="0.48"/>
      <inertia ixx="0.0032910599999999997" ixy="8.32e-06" ixz="0.00044358" iyy="0.00375998" iyz="7.18e-06" izz="0.00221683"/>
    </inertial>
  </link>
  <link name="head_link1">
    <visual>
      <origin rpy="0 0 0" xyz="0 0 0"/>
      <geometry>
        <mesh filename="package://galbot_g1_description/meshes/v2_2_1/visual/high/head_link1.obj"/>
      </geometry>
    </visual>
    <inertial>
      <origin rpy="0.0 0.0 0.0" xyz="-2e-05 0.00709 -0.0559"/>
      <mass value="1.5695"/>
      <inertia ixx="0.0069002956" ixy="1.52205e-06" ixz="3.13295e-06" iyy="0.00683300359" iyz="1.009318e-05" izz="0.00116967635"/>
    </inertial>
    <collision>
      <origin rpy="0 0 0" xyz="0 0 0"/>
      <geometry>
        <mesh filename="package://galbot_g1_description/meshes/v2_2_1/collision/convex_hull/head_link1.stl"/>
      </geometry>
    </collision>
  </link>
  <joint name="head_joint1" type="revolute">
    <origin rpy="0.0 0.0 0.0" xyz="0.0 0.0 0.0"/>
    <parent link="head_base_link"/>
    <child link="head_link1"/>
    <axis xyz="0.0 0.0 1.0"/>
    <limit effort="4.0" lower="-1.5208" upper="1.5208" velocity="1.5"/>
  </joint>
  <link name="head_link2">
    <visual>
      <origin rpy="0 0 0" xyz="0 0 0"/>
      <geometry>
        <mesh filename="package://galbot_g1_description/meshes/v2_2_1/visual/high/head_link2.obj"/>
      </geometry>
    </visual>
    <inertial>
      <origin rpy="0.0 0.0 0.0" xyz="0.01835 -0.033479999999999996 0.00642"/>
      <mass value="0.81"/>
      <inertia ixx="3.99161e-06" ixy="1.29825e-06" ixz="3.92e-09" iyy="3.72602e-06" iyz="7.75e-09" izz="5.53062e-06"/>
    </inertial>
    <collision>
      <origin rpy="0 0 0" xyz="0 0 0"/>
      <geometry>
        <mesh filename="package://galbot_g1_description/meshes/v2_2_1/collision/convex_hull/head_link2.stl"/>
      </geometry>
    </collision>
  </link>
  <joint name="head_joint2" type="revolute">
    <origin rpy="-1.5707963267948966 0.0 0.0" xyz="0.0 0.0 0.0"/>
    <parent link="head_link1"/>
    <child link="head_link2"/>
    <axis xyz="0.0 0.0 1.0"/>
    <limit effort="4.0" lower="-0.2143461" upper="0.4935988" velocity="1.5"/>
  </joint>
  <link name="head_end_effector_mount_link">
    <inertial>
      <origin rpy="0.0 0.0 0.0" xyz="0.0 0.0 0.0"/>
      <mass value="0.0"/>
      <inertia ixx="0.0" ixy="0.0" ixz="0.0" iyy="0.0" iyz="0.0" izz="0.0"/>
    </inertial>
  </link>
  <joint name="head_end_effector_mount_joint" type="fixed">
    <origin rpy="0.0 0.0 0.0" xyz="0.0 0.0 0.0"/>
    <parent link="head_link2"/>
    <child link="head_end_effector_mount_link"/>
  </joint>
  <joint name="left_arm_base_joint" type="fixed">
    <origin rpy="0.0 0.0 0.0" xyz="0.0 0.0 0.0"/>
    <parent link="torso_left_arm_mount_link"/>
    <child link="left_arm_base_link"/>
  </joint>
  <link name="left_arm_base_link">
    <inertial>
      <origin rpy="0.0 0.0 0.0" xyz="0.0 0.0 -0.10506"/>
      <mass value="0.92"/>
      <inertia ixx="0.01075595" ixy="9e-08" ixz="4.1e-07" iyy="0.01077842" iyz="1.896e-05" izz="0.0007042000000000001"/>
    </inertial>
  </link>
  <link name="left_arm_link1">
    <visual>
      <origin rpy="0 0 0" xyz="0 0 0"/>
      <geometry>
        <mesh filename="package://galbot_g1_description/meshes/v2_2_1/visual/high/left_arm_link1.obj"/>
      </geometry>
    </visual>
    <inertial>
      <origin rpy="0.0 0.0 0.0" xyz="0.0 0.0009699999999999999 -0.015390000000000001"/>
      <mass value="1.6"/>
      <inertia ixx="0.00332981" ixy="1.8920000000000002e-05" ixz="6.9e-07" iyy="0.00339121" iyz="2.9760000000000003e-05" izz="0.0016524"/>
    </inertial>
    <collision>
      <origin rpy="0 0 0" xyz="0 0 0"/>
      <geometry>
        <mesh filename="package://galbot_g1_description/meshes/v2_2_1/collision/convex_hull/left_arm_link1.stl"/>
      </geometry>
    </collision>
  </link>
  <joint name="left_arm_joint1" type="revolute">
    <origin rpy="0.0 0.0 0.523598775598286" xyz="0.0 0.0 0.0"/>
    <parent link="left_arm_base_link"/>
    <child link="left_arm_link1"/>
    <axis xyz="0.0 0.0 1.0"/>
    <limit effort="60.0" lower="-3.00432619" upper="3.00432619" velocity="1.5"/>
  </joint>
  <link name="left_arm_link2">
    <visual>
      <origin rpy="0 0 0" xyz="0 0 0"/>
      <geometry>
        <mesh filename="package://galbot_g1_description/meshes/v2_2_1/visual/high/left_arm_link2.obj"/>
      </geometry>
    </visual>
    <inertial>
      <origin rpy="0.0 0.0 0.0" xyz="0.0 0.09558 0.010150000000000001"/>
      <mass value="1.43"/>
      <inertia ixx="0.01937881" ixy="2.0000000000000002e-07" ixz="1.2e-07" iyy="0.0015791400000000001" iyz="0.00019578" izz="0.018951810000000003"/>
    </inertial>
    <collision>
      <origin rpy="0 0 0" xyz="0 0 0"/>
      <geometry>
        <mesh filename="package://galbot_g1_description/meshes/v2_2_1/collision/convex_hull/left_arm_link2.stl"/>
      </geometry>
    </collision>
  </link>
  <joint name="left_arm_joint2" type="revolute">
    <origin rpy="1.5707963267949 0.0 3.14159265358979" xyz="0.0 0.0 0.0"/>
    <parent link="left_arm_link1"/>
    <child link="left_arm_link2"/>
    <axis xyz="0.0 0.0 1.0"/>
    <limit effort="60.0" lower="-1.608062789" upper="1.608062789" velocity="1.5"/>
  </joint>
  <link name="left_arm_link3">
    <visual>
      <origin rpy="0 0 0" xyz="0 0 0"/>
      <geometry>
        <mesh filename="package://galbot_g1_description/meshes/v2_2_1/visual/high/left_arm_link3.obj"/>
      </geometry>
    </visual>
    <inertial>
      <origin rpy="0.0 0.0 0.0" xyz="0.0 0.00088 -0.04936"/>
      <mass value="1.43"/>
      <inertia ixx="0.01187457" ixy="1.5e-07" ixz="8.5e-07" iyy="0.01178759" iyz="0.00010048" izz="0.0013715"/>
    </inertial>
    <collision>
      <origin rpy="0 0 0" xyz="0 0 0"/>
      <geometry>
        <mesh filename="package://galbot_g1_description/meshes/v2_2_1/collision/convex_hull/left_arm_link3.stl"/>
      </geometry>
    </collision>
  </link>
  <joint name="left_arm_joint3" type="revolute">
    <origin rpy="1.5707963267949 1.0471975511966 -3.14159265358979" xyz="0.0 0.35 0.0"/>
    <parent link="left_arm_link2"/>
    <child link="left_arm_link3"/>
    <axis xyz="0.0 0.0 1.0"/>
    <limit effort="30.0" lower="-2.916972222" upper="2.916972222" velocity="1.5"/>
  </joint>
  <link name="left_arm_link4">
    <visual>
      <origin rpy="0 0 0" xyz="0 0 0"/>
      <geometry>
        <mesh filename="package://galbot_g1_description/meshes/v2_2_1/visual/high/left_arm_link4.obj"/>
      </geometry>
    </visual>
    <inertial>
      <origin rpy="0.0 0.0 0.0" xyz="0.0 0.05614 0.019170000000000003"/>
      <mass value="1.1"/>
      <inertia ixx="0.00701388" ixy="3.2e-07" ixz="1.16e-06" iyy="0.00161854" iyz="0.00033944" izz="0.0065011999999999995"/>
    </inertial>
    <collision>
      <origin rpy="0 0 0" xyz="0 0 0"/>
      <geometry>
        <mesh filename="package://galbot_g1_description/meshes/v2_2_1/collision/convex_hull/left_arm_link4.stl"/>
      </geometry>
    </collision>
  </link>
  <joint name="left_arm_joint4" type="revolute">
    <origin rpy="1.5707963267949 0.0 -3.14159265358979" xyz="0.0 0.0 0.0"/>
    <parent link="left_arm_link3"/>
    <child link="left_arm_link4"/>
    <axis xyz="0.0 0.0 1.0"/>
    <limit effort="30.0" lower="-2.5679938779914946" upper="1.869862177" velocity="1.5"/>
  </joint>
  <link name="left_arm_link5">
    <visual>
      <origin rpy="0 0 0" xyz="0 0 0"/>
      <geometry>
        <mesh filename="package://galbot_g1_description/meshes/v2_2_1/visual/high/left_arm_link5.obj"/>
      </geometry>
    </visual>
    <inertial>
      <origin rpy="0.0 0.0 0.0" xyz="0.00044 0.0016899999999999999 -0.13306"/>
      <mass value="1.15"/>
      <inertia ixx="0.025809930000000002" ixy="1.98e-05" ixz="5.605e-05" iyy="0.02530313" iyz="0.00020931999999999998" izz="0.00115848"/>
    </inertial>
    <collision>
      <origin rpy="0 0 0" xyz="0 0 0"/>
      <geometry>
        <mesh filename="package://galbot_g1_description/meshes/v2_2_1/collision/convex_hull/left_arm_link5.stl"/>
      </geometry>
    </collision>
  </link>
  <joint name="left_arm_joint5" type="revolute">
    <origin rpy="-1.5707963267949 0.0 0.0" xyz="0.0 0.36 0.0"/>
    <parent link="left_arm_link4"/>
    <child link="left_arm_link5"/>
    <axis xyz="0.0 0.0 1.0"/>
    <limit effort="10.0" lower="-2.916972222" upper="2.916972222" velocity="1.5"/>
  </joint>
  <link name="left_arm_link6">
    <visual>
      <origin rpy="0 0 0" xyz="0 0 0"/>
      <geometry>
        <mesh filename="package://galbot_g1_description/meshes/v2_2_1/visual/high/left_arm_link6.obj"/>
      </geometry>
    </visual>
    <inertial>
      <origin rpy="0.0 0.0 0.0" xyz="-0.00088 -0.0072699999999999996 -0.00011999999999999999"/>
      <mass value="0.47"/>
      <inertia ixx="0.00027557" ixy="7.900000000000001e-07" ixz="1.48e-06" iyy="0.00028977999999999995" iyz="2.25e-06" izz="0.00029684"/>
    </inertial>
    <collision>
      <origin rpy="0 0 0" xyz="0 0 0"/>
      <geometry>
        <mesh filename="package://galbot_g1_description/meshes/v2_2_1/collision/convex_hull/left_arm_link6.stl"/>
      </geometry>
    </collision>
  </link>
  <joint name="left_arm_joint6" type="revolute">
    <origin rpy="1.5707963267949 1.5707963267949 0.0" xyz="0.0 0.0 0.0"/>
    <parent link="left_arm_link5"/>
    <child link="left_arm_link6"/>
    <axis xyz="0.0 0.0 1.0"/>
    <limit effort="10.0" lower="-0.8226646259971648" upper="0.7353981633974483" velocity="1.5"/>
  </joint>
  <link name="left_arm_link7">
    <visual>
      <origin rpy="0 0 0" xyz="0 0 0"/>
      <geometry>
        <mesh filename="package://galbot_g1_description/meshes/v2_2_1/visual/high/left_arm_link7.obj"/>
      </geometry>
    </visual>
    <inertial>
      <origin rpy="0.0 0.0 0.0" xyz="-0.05776 -0.00675 0.011349999999999999"/>
      <mass value="0.8"/>
      <inertia ixx="0.00116375" ixy="0.00033236" ixz="0.00014869" iyy="0.00424012" iyz="6.570000000000001e-06" izz="0.00418879"/>
    </inertial>
    <collision>
      <origin rpy="0 0 0" xyz="0 0 0"/>
      <geometry>
        <mesh filename="package://galbot_g1_description/meshes/v2_2_1/collision/convex_hull/left_arm_link7.stl"/>
      </geometry>
    </collision>
  </link>
  <joint name="left_arm_joint7" type="revolute">
    <origin rpy="1.5707963267949 0.0 0.0" xyz="0.0 0.0 0.0"/>
    <parent link="left_arm_link6"/>
    <child link="left_arm_link7"/>
    <axis xyz="0.0 0.0 1.0"/>
    <limit effort="10.0" lower="-1.538202778" upper="1.538202778" velocity="1.5"/>
  </joint>
  <link name="left_arm_end_effector_mount_link">
    <inertial>
      <origin rpy="0.0 0.0 0.0" xyz="0.0 0.0 0.0"/>
      <mass value="0.0"/>
      <inertia ixx="0.0" ixy="0.0" ixz="0.0" iyy="0.0" iyz="0.0" izz="0.0"/>
    </inertial>
  </link>
  <joint name="left_arm_end_effector_mount_joint" type="fixed">
    <origin rpy="3.14159265358979 0.0 3.14159265358979" xyz="-0.10926 0.0 0.0"/>
    <parent link="left_arm_link7"/>
    <child link="left_arm_end_effector_mount_link"/>
  </joint>
  <link name="left_wrist_camera_link">
    <visual>
      <origin rpy="0 0 0" xyz="0 0 0"/>
      <geometry>
        <mesh filename="package://galbot_g1_description/meshes/v2_2_1/visual/high/left_wrist_camera_link.obj"/>
      </geometry>
    </visual>
    <inertial>
      <origin rpy="0.0 0.0 0.0" xyz="-0.0687164275307753 0.00742418594708705 -0.0656976688947199"/>
      <mass value="0.0533223543172611"/>
      <inertia ixx="2.57961610647567e-05" ixy="-4.79475020826079e-07" ixz="-1.78893716134214e-06" iyy="1.37594261317448e-05" iyz="2.73965367892125e-07" izz="1.70502507719673e-05"/>
    </inertial>
    <collision>
      <origin rpy="0 0 0" xyz="0 0 0"/>
      <geometry>
        <mesh filename="package://galbot_g1_description/meshes/v2_2_1/collision/convex_hull/left_wrist_camera_link.stl"/>
      </geometry>
    </collision>
  </link>
  <joint name="left_wrist_camera_joint" type="fixed">
    <origin rpy="0.0 0.0 0.0" xyz="0.0 0.0 0.0"/>
    <parent link="left_arm_link7"/>
    <child link="left_wrist_camera_link"/>
  </joint>
  <joint name="left_gripper_joint" type="fixed">
    <origin rpy="0 0 0" xyz="0 0 0"/>
    <parent link="left_arm_end_effector_mount_link"/>
    <child link="left_gripper_flange_link"/>
  </joint>
  <link name="left_gripper_flange_link">
    <visual>
      <origin rpy="0 0 0" xyz="0 0 0"/>
      <geometry>
        <mesh filename="package://galbot_g1_description/tools/galbot_ge101in_description/meshes/v1_0_0/visual/high/left_gripper_flange_link.obj"/>
      </geometry>
    </visual>
    <inertial>
      <origin rpy="0.0 0.0 0.0" xyz="0.0030662 -1.4019e-18 3.383e-18"/>
      <mass value="0.031005"/>
      <inertia ixx="2.2585e-05" ixy="-2.0366e-21" ixz="-3.7461e-22" iyy="1.141e-05" iyz="-7.8518e-23" izz="1.141e-05"/>
    </inertial>
    <collision>
      <origin rpy="0 0 0" xyz="0 0 0"/>
      <geometry>
        <mesh filename="package://galbot_g1_description/tools/galbot_ge101in_description/meshes/v1_0_0/collision/convex_hull/left_gripper_flange_link.stl"/>
      </geometry>
    </collision>
  </link>
  <link name="left_gripper_base_link">
    <visual>
      <origin rpy="0 0 0" xyz="0 0 0"/>
      <geometry>
        <mesh filename="package://galbot_g1_description/tools/galbot_ge101in_description/meshes/v1_0_0/visual/high/left_gripper_base_link.obj"/>
      </geometry>
    </visual>
    <inertial>
      <origin rpy="0.0 0.0 0.0" xyz="0.037051 -6.4001e-05 6.4706e-05"/>
      <mass value="0.061747"/>
      <inertia ixx="2.5813e-05" ixy="4.7224e-08" ixz="-3.9403e-11" iyy="7.2859e-05" iyz="-2.962e-10" izz="5.7173e-05"/>
    </inertial>
    <collision>
      <origin rpy="0 0 0" xyz="0 0 0"/>
      <geometry>
        <mesh filename="package://galbot_g1_description/tools/galbot_ge101in_description/meshes/v1_0_0/collision/convex_hull/left_gripper_base_link.stl"/>
      </geometry>
    </collision>
  </link>
  <joint name="left_gripper_base_joint" type="fixed">
    <origin rpy="0.0 0.0 0.0" xyz="0.0065 0.0 0.0"/>
    <parent link="left_gripper_flange_link"/>
    <child link="left_gripper_base_link"/>
  </joint>
  <link name="left_gripper_l_knuckle_link">
    <visual>
      <origin rpy="0 0 0" xyz="0 0 0"/>
      <geometry>
        <mesh filename="package://galbot_g1_description/tools/galbot_ge101in_description/meshes/v1_0_0/visual/high/left_gripper_l_knuckle_link.obj"/>
      </geometry>
    </visual>
    <inertial>
      <origin rpy="0.0 0.0 0.0" xyz="0.024101 0.0 0.0"/>
      <mass value="0.0070682"/>
      <inertia ixx="9.2131e-08" ixy="0.0" ixz="0.0" iyy="1.559e-06" iyz="0.0" izz="1.4931e-06"/>
    </inertial>
    <collision>
      <origin rpy="0 0 0" xyz="0 0 0"/>
      <geometry>
        <mesh filename="package://galbot_g1_description/tools/galbot_ge101in_description/meshes/v1_0_0/collision/convex_hull/left_gripper_l_knuckle_link.stl"/>
      </geometry>
    </collision>
  </link>
  <joint name="left_gripper_l_knuckle_joint" type="revolute">
    <origin rpy="1.5707963267948966 1.2465 0.0" xyz="0.0745 0.0 -0.0385"/>
    <parent link="left_gripper_base_link"/>
    <child link="left_gripper_l_knuckle_link"/>
    <axis xyz="0.0 0.0 1.0"/>
    <limit effort="50.0" lower="-3.13" upper="3.13" velocity="0.5"/>
    <mimic joint="left_gripper_r_knuckle_joint" multiplier="1.0" offset="0.0"/>
  </joint>
  <link name="left_gripper_l_inner_knuckle_link">
    <visual>
      <origin rpy="0 0 0" xyz="0 0 0"/>
      <geometry>
        <mesh filename="package://galbot_g1_description/tools/galbot_ge101in_description/meshes/v1_0_0/visual/high/left_gripper_l_inner_knuckle_link.obj"/>
      </geometry>
    </visual>
    <inertial>
      <origin rpy="0.0 0.0 0.0" xyz="0.023769 0.0 0.0"/>
      <mass value="0.007802"/>
      <inertia ixx="1.044e-07" ixy="0.0" ixz="0.0" iyy="1.6385e-06" iyz="0.0" izz="1.566e-06"/>
    </inertial>
    <collision>
      <origin rpy="0 0 0" xyz="0 0 0"/>
      <geometry>
        <mesh filename="package://galbot_g1_description/tools/galbot_ge101in_description/meshes/v1_0_0/collision/convex_hull/left_gripper_l_inner_knuckle_link.stl"/>
      </geometry>
    </collision>
  </link>
  <joint name="left_gripper_l_inner_knuckle_joint" type="revolute">
    <origin rpy="1.5707963267948966 1.2465 0.0" xyz="0.079 0.0 -0.026"/>
    <parent link="left_gripper_base_link"/>
    <child link="left_gripper_l_inner_knuckle_link"/>
    <axis xyz="0.0 0.0 1.0"/>
    <limit effort="1000.0" lower="-3.13" upper="3.13" velocity="2.0"/>
    <mimic joint="left_gripper_r_knuckle_joint" multiplier="1.0" offset="0.0"/>
  </joint>
  <link name="left_gripper_l_finger_link">
    <visual>
      <origin rpy="0 0 0" xyz="0 0 0"/>
      <geometry>
        <mesh filename="package://galbot_g1_description/tools/galbot_ge101in_description/meshes/v1_0_0/visual/high/left_gripper_l_finger_link.obj"/>
      </geometry>
    </visual>
    <inertial>
      <origin rpy="0.0 0.0 0.0" xyz="0.016809 0.0019094 0.0"/>
      <mass value="0.015957"/>
      <inertia ixx="5.5426e-07" ixy="0.0" ixz="0.0" iyy="1.8538e-06" iyz="0.0" izz="1.5262e-06"/>
    </inertial>
    <collision>
      <origin rpy="0 0 0" xyz="0 0 0"/>
      <geometry>
        <mesh filename="package://galbot_g1_description/tools/galbot_ge101in_description/meshes/v1_0_0/collision/convex_hull/left_gripper_l_finger_link.stl"/>
      </geometry>
    </collision>
  </link>
  <joint name="left_gripper_l_finger_joint" type="revolute">
    <origin rpy="0.0 0.0 1.2465" xyz="0.045 0.0 0.0"/>
    <parent link="left_gripper_l_inner_knuckle_link"/>
    <child link="left_gripper_l_finger_link"/>
    <axis xyz="0.0 0.0 1.0"/>
    <limit effort="1000.0" lower="-3.13" upper="3.13" velocity="2.0"/>
    <mimic joint="left_gripper_r_knuckle_joint" multiplier="-1.0" offset="0.0"/>
  </joint>
  <link name="left_gripper_r_knuckle_link">
    <visual>
      <origin rpy="0 0 0" xyz="0 0 0"/>
      <geometry>
        <mesh filename="package://galbot_g1_description/tools/galbot_ge101in_description/meshes/v1_0_0/visual/high/left_gripper_r_knuckle_link.obj"/>
      </geometry>
    </visual>
    <inertial>
      <origin rpy="0.0 0.0 0.0" xyz="0.024101 0.0 0.0"/>
      <mass value="0.0070682"/>
      <inertia ixx="9.2131e-08" ixy="0.0" ixz="0.0" iyy="1.559e-06" iyz="0.0" izz="1.4931e-06"/>
    </inertial>
    <collision>
      <origin rpy="0 0 0" xyz="0 0 0"/>
      <geometry>
        <mesh filename="package://galbot_g1_description/tools/galbot_ge101in_description/meshes/v1_0_0/collision/convex_hull/left_gripper_r_knuckle_link.stl"/>
      </geometry>
    </collision>
  </link>
  <joint name="left_gripper_r_knuckle_joint" type="revolute">
    <origin rpy="1.5707963267948966 -1.2465 0.0" xyz="0.0745 0.0 0.0385"/>
    <parent link="left_gripper_base_link"/>
    <child link="left_gripper_r_knuckle_link"/>
    <axis xyz="0.0 0.0 -1.0"/>
    <limit effort="50.0" lower="0.0" upper="1.703" velocity="0.5"/>
  </joint>
  <link name="left_gripper_r_inner_knuckle_link">
    <visual>
      <origin rpy="0 0 0" xyz="0 0 0"/>
      <geometry>
        <mesh filename="package://galbot_g1_description/tools/galbot_ge101in_description/meshes/v1_0_0/visual/high/left_gripper_r_inner_knuckle_link.obj"/>
      </geometry>
    </visual>
    <inertial>
      <origin rpy="0.0 0.0 0.0" xyz="0.023769 0.0 0.0"/>
      <mass value="0.007802"/>
      <inertia ixx="1.044e-07" ixy="0.0" ixz="0.0" iyy="1.6385e-06" iyz="0.0" izz="1.566e-06"/>
    </inertial>
    <collision>
      <origin rpy="0 0 0" xyz="0 0 0"/>
      <geometry>
        <mesh filename="package://galbot_g1_description/tools/galbot_ge101in_description/meshes/v1_0_0/collision/convex_hull/left_gripper_r_inner_knuckle_link.stl"/>
      </geometry>
    </collision>
  </link>
  <joint name="left_gripper_r_inner_knuckle_joint" type="revolute">
    <origin rpy="1.5707963267948966 -1.2465 0.0" xyz="0.079 0.0 0.026"/>
    <parent link="left_gripper_base_link"/>
    <child link="left_gripper_r_inner_knuckle_link"/>
    <axis xyz="0.0 0.0 1.0"/>
    <limit effort="1000.0" lower="-3.13" upper="3.13" velocity="2.0"/>
    <mimic joint="left_gripper_r_knuckle_joint" multiplier="-1.0" offset="0.0"/>
  </joint>
  <link name="left_gripper_r_finger_link">
    <visual>
      <origin rpy="0 0 0" xyz="0 0 0"/>
      <geometry>
        <mesh filename="package://galbot_g1_description/tools/galbot_ge101in_description/meshes/v1_0_0/visual/high/left_gripper_r_finger_link.obj"/>
      </geometry>
    </visual>
    <inertial>
      <origin rpy="0.0 0.0 0.0" xyz="0.016809 -0.0019094 0.0"/>
      <mass value="0.015957"/>
      <inertia ixx="5.5426e-07" ixy="0.0" ixz="0.0" iyy="1.8538e-06" iyz="0.0" izz="1.5262e-06"/>
    </inertial>
    <collision>
      <origin rpy="0 0 0" xyz="0 0 0"/>
      <geometry>
        <mesh filename="package://galbot_g1_description/tools/galbot_ge101in_description/meshes/v1_0_0/collision/convex_hull/left_gripper_r_finger_link.stl"/>
      </geometry>
    </collision>
  </link>
  <joint name="left_gripper_r_finger_joint" type="revolute">
    <origin rpy="0.0 0.0 -1.2465" xyz="0.045 0.0 0.0"/>
    <parent link="left_gripper_r_inner_knuckle_link"/>
    <child link="left_gripper_r_finger_link"/>
    <axis xyz="0.0 0.0 1.0"/>
    <limit effort="1000.0" lower="-3.13" upper="3.13" velocity="2.0"/>
    <mimic joint="left_gripper_r_knuckle_joint" multiplier="1.0" offset="0.0"/>
  </joint>
  <link name="left_gripper_tcp_link">
    <inertial>
      <origin rpy="0 0 0" xyz="0 0 0"/>
      <mass value="0"/>
      <inertia ixx="0" ixy="0" ixz="0" iyy="0" iyz="0" izz="0"/>
    </inertial>
  </link>
  <joint name="left_gripper_tcp_joint" type="fixed">
    <origin rpy="-1.5707963267948966 0.0 0.0" xyz="0.13996 0.0 0.0"/>
    <parent link="left_gripper_base_link"/>
    <child link="left_gripper_tcp_link"/>
  </joint>
  <joint name="right_arm_base_joint" type="fixed">
    <origin rpy="0.0 0.0 0.0" xyz="0.0 0.0 0.0"/>
    <parent link="torso_right_arm_mount_link"/>
    <child link="right_arm_base_link"/>
  </joint>
  <link name="right_arm_base_link">
    <inertial>
      <origin rpy="0.0 0.0 0.0" xyz="0.0 0.0 -0.10506"/>
      <mass value="0.92"/>
      <inertia ixx="0.01075595" ixy="9e-08" ixz="4.1e-07" iyy="0.01077842" iyz="1.896e-05" izz="0.0007042000000000001"/>
    </inertial>
  </link>
  <link name="right_arm_link1">
    <visual>
      <origin rpy="0 0 0" xyz="0 0 0"/>
      <geometry>
        <mesh filename="package://galbot_g1_description/meshes/v2_2_1/visual/high/right_arm_link1.obj"/>
      </geometry>
    </visual>
    <inertial>
      <origin rpy="0.0 0.0 0.0" xyz="0.0 -0.0009699999999999999 -0.015390000000000001"/>
      <mass value="1.6"/>
      <inertia ixx="0.00332981" ixy="1.8920000000000002e-05" ixz="6.9e-07" iyy="0.00339121" iyz="2.9760000000000003e-05" izz="0.0016524"/>
    </inertial>
    <collision>
      <origin rpy="0 0 0" xyz="0 0 0"/>
      <geometry>
        <mesh filename="package://galbot_g1_description/meshes/v2_2_1/collision/convex_hull/right_arm_link1.stl"/>
      </geometry>
    </collision>
  </link>
  <joint name="right_arm_joint1" type="revolute">
    <origin rpy="0.0 0.0 -0.523598775598286" xyz="0.0 0.0 0.0"/>
    <parent link="right_arm_base_link"/>
    <child link="right_arm_link1"/>
    <axis xyz="0.0 0.0 1.0"/>
    <limit effort="60.0" lower="-3.00432619" upper="3.00432619" velocity="1.5"/>
  </joint>
  <link name="right_arm_link2">
    <visual>
      <origin rpy="0 0 0" xyz="0 0 0"/>
      <geometry>
        <mesh filename="package://galbot_g1_description/meshes/v2_2_1/visual/high/right_arm_link2.obj"/>
      </geometry>
    </visual>
    <inertial>
      <origin rpy="0.0 0.0 0.0" xyz="0.0 -0.09558 0.010150000000000001"/>
      <mass value="1.43"/>
      <inertia ixx="0.01937881" ixy="2.0000000000000002e-07" ixz="1.2e-07" iyy="0.0015791400000000001" iyz="0.00019578" izz="0.018951810000000003"/>
    </inertial>
    <collision>
      <origin rpy="0 0 0" xyz="0 0 0"/>
      <geometry>
        <mesh filename="package://galbot_g1_description/meshes/v2_2_1/collision/convex_hull/right_arm_link2.stl"/>
      </geometry>
    </collision>
  </link>
  <joint name="right_arm_joint2" type="revolute">
    <origin rpy="-1.5707963267949 0.0 3.14159265358979" xyz="0.0 0.0 0.0"/>
    <parent link="right_arm_link1"/>
    <child link="right_arm_link2"/>
    <axis xyz="0.0 0.0 1.0"/>
    <limit effort="60.0" lower="-1.608062789" upper="1.608062789" velocity="1.5"/>
  </joint>
  <link name="right_arm_link3">
    <visual>
      <origin rpy="0 0 0" xyz="0 0 0"/>
      <geometry>
        <mesh filename="package://galbot_g1_description/meshes/v2_2_1/visual/high/right_arm_link3.obj"/>
      </geometry>
    </visual>
    <inertial>
      <origin rpy="0.0 0.0 0.0" xyz="0.0 -0.00088 -0.04936"/>
      <mass value="1.43"/>
      <inertia ixx="0.01187457" ixy="1.5e-07" ixz="8.5e-07" iyy="0.01178759" iyz="0.00010048" izz="0.0013715"/>
    </inertial>
    <collision>
      <origin rpy="0 0 0" xyz="0 0 0"/>
      <geometry>
        <mesh filename="package://galbot_g1_description/meshes/v2_2_1/collision/convex_hull/right_arm_link3.stl"/>
      </geometry>
    </collision>
  </link>
  <joint name="right_arm_joint3" type="revolute">
    <origin rpy="-1.5707963267949 1.04719755119629 -3.14159265358979" xyz="0.0 -0.35 0.0"/>
    <parent link="right_arm_link2"/>
    <child link="right_arm_link3"/>
    <axis xyz="0.0 0.0 1.0"/>
    <limit effort="30.0" lower="-2.916972222" upper="2.916972222" velocity="1.5"/>
  </joint>
  <link name="right_arm_link4">
    <visual>
      <origin rpy="0 0 0" xyz="0 0 0"/>
      <geometry>
        <mesh filename="package://galbot_g1_description/meshes/v2_2_1/visual/high/right_arm_link4.obj"/>
      </geometry>
    </visual>
    <inertial>
      <origin rpy="0.0 0.0 0.0" xyz="0.0 -0.05614 0.019170000000000003"/>
      <mass value="1.1"/>
      <inertia ixx="0.00701388" ixy="3.2e-07" ixz="1.16e-06" iyy="0.00161854" iyz="0.00033944" izz="0.0065011999999999995"/>
    </inertial>
    <collision>
      <origin rpy="0 0 0" xyz="0 0 0"/>
      <geometry>
        <mesh filename="package://galbot_g1_description/meshes/v2_2_1/collision/convex_hull/right_arm_link4.stl"/>
      </geometry>
    </collision>
  </link>
  <joint name="right_arm_joint4" type="revolute">
    <origin rpy="-1.57079632679459 0.0 3.14159265358979" xyz="0.0 0.0 0.0"/>
    <parent link="right_arm_link3"/>
    <child link="right_arm_link4"/>
    <axis xyz="0.0 0.0 1.0"/>
    <limit effort="30.0" lower="-1.869862177" upper="2.5679938779914946" velocity="1.5"/>
  </joint>
  <link name="right_arm_link5">
    <visual>
      <origin rpy="0 0 0" xyz="0 0 0"/>
      <geometry>
        <mesh filename="package://galbot_g1_description/meshes/v2_2_1/visual/high/right_arm_link5.obj"/>
      </geometry>
    </visual>
    <inertial>
      <origin rpy="0.0 0.0 0.0" xyz="0.00044 0.0016899999999999999 -0.13306"/>
      <mass value="1.15"/>
      <inertia ixx="0.025809930000000002" ixy="1.98e-05" ixz="5.605e-05" iyy="0.02530313" iyz="0.00020931999999999998" izz="0.00115848"/>
    </inertial>
    <collision>
      <origin rpy="0 0 0" xyz="0 0 0"/>
      <geometry>
        <mesh filename="package://galbot_g1_description/meshes/v2_2_1/collision/convex_hull/right_arm_link5.stl"/>
      </geometry>
    </collision>
  </link>
  <joint name="right_arm_joint5" type="revolute">
    <origin rpy="-1.5707963267949 0.0 3.14159265358979" xyz="0.0 -0.36 0.0"/>
    <parent link="right_arm_link4"/>
    <child link="right_arm_link5"/>
    <axis xyz="0.0 0.0 1.0"/>
    <limit effort="10.0" lower="-2.916972222" upper="2.916972222" velocity="1.5"/>
  </joint>
  <link name="right_arm_link6">
    <visual>
      <origin rpy="0 0 0" xyz="0 0 0"/>
      <geometry>
        <mesh filename="package://galbot_g1_description/meshes/v2_2_1/visual/high/right_arm_link6.obj"/>
      </geometry>
    </visual>
    <inertial>
      <origin rpy="0.0 0.0 0.0" xyz="-0.00088 0.0072699999999999996 -0.00011999999999999999"/>
      <mass value="0.47"/>
      <inertia ixx="0.00027557" ixy="7.6e-07" ixz="1.44e-06" iyy="0.00028977999999999995" iyz="2.25e-06" izz="0.00029684"/>
    </inertial>
    <collision>
      <origin rpy="0 0 0" xyz="0 0 0"/>
      <geometry>
        <mesh filename="package://galbot_g1_description/meshes/v2_2_1/collision/convex_hull/right_arm_link6.stl"/>
      </geometry>
    </collision>
  </link>
  <joint name="right_arm_joint6" type="revolute">
    <origin rpy="1.5707963267949 1.5707963267949 0.0" xyz="0.0 0.0 0.0"/>
    <parent link="right_arm_link5"/>
    <child link="right_arm_link6"/>
    <axis xyz="0.0 0.0 1.0"/>
    <limit effort="10.0" lower="-0.7353981633974483" upper="0.8226646259971648" velocity="1.5"/>
  </joint>
  <link name="right_arm_link7">
    <visual>
      <origin rpy="0 0 0" xyz="0 0 0"/>
      <geometry>
        <mesh filename="package://galbot_g1_description/meshes/v2_2_1/visual/high/right_arm_link7.obj"/>
      </geometry>
    </visual>
    <inertial>
      <origin rpy="0.0 0.0 0.0" xyz="-0.05751 0.00684 0.011869999999999999"/>
      <mass value="0.8"/>
      <inertia ixx="0.00117613" ixy="0.00033793" ixz="0.0001662" iyy="0.00423935" iyz="8.589999999999999e-06" izz="0.00417642"/>
    </inertial>
    <collision>
      <origin rpy="0 0 0" xyz="0 0 0"/>
      <geometry>
        <mesh filename="package://galbot_g1_description/meshes/v2_2_1/collision/convex_hull/right_arm_link7.stl"/>
      </geometry>
    </collision>
  </link>
  <joint name="right_arm_joint7" type="revolute">
    <origin rpy="-1.5707963267949 0.0 0.0" xyz="0.0 0.0 0.0"/>
    <parent link="right_arm_link6"/>
    <child link="right_arm_link7"/>
    <axis xyz="0.0 0.0 1.0"/>
    <limit effort="10.0" lower="-1.538202778" upper="1.538202778" velocity="1.5"/>
  </joint>
  <link name="right_arm_end_effector_mount_link">
    <inertial>
      <origin rpy="0.0 0.0 0.0" xyz="0.0 0.0 0.0"/>
      <mass value="0.0"/>
      <inertia ixx="0.0" ixy="0.0" ixz="0.0" iyy="0.0" iyz="0.0" izz="0.0"/>
    </inertial>
  </link>
  <joint name="right_arm_end_effector_mount_joint" type="fixed">
    <origin rpy="3.14159265358979 0.0 3.14159265358948" xyz="-0.10926 0.0 0.0"/>
    <parent link="right_arm_link7"/>
    <child link="right_arm_end_effector_mount_link"/>
  </joint>
  <link name="right_wrist_camera_link">
    <visual>
      <origin rpy="0 0 0" xyz="0 0 0"/>
      <geometry>
        <mesh filename="package://galbot_g1_description/meshes/v2_2_1/visual/high/right_wrist_camera_link.obj"/>
      </geometry>
    </visual>
    <inertial>
      <origin rpy="0.0 0.0 0.0" xyz="-0.0621229724155358 -0.0628379837355285 -0.00140310958315455"/>
      <mass value="0.0492751941348016"/>
      <inertia ixx="3.66069470547417e-05" ixy="-3.55284385731841e-07" ixz="3.8533182318026e-07" iyy="3.08593710158624e-05" iyz="-3.07292981503681e-07" izz="8.80145863410975e-06"/>
    </inertial>
    <collision>
      <origin rpy="0 0 0" xyz="0 0 0"/>
      <geometry>
        <mesh filename="package://galbot_g1_description/meshes/v2_2_1/collision/convex_hull/right_wrist_camera_link.stl"/>
      </geometry>
    </collision>
  </link>
  <joint name="right_wrist_camera_joint" type="fixed">
    <origin rpy="0.0 0.0 0.0" xyz="0.0 0.0 0.0"/>
    <parent link="right_arm_link7"/>
    <child link="right_wrist_camera_link"/>
  </joint>
  <joint name="right_gripper_joint" type="fixed">
    <origin rpy="0 0 0" xyz="0 0 0"/>
    <parent link="right_arm_end_effector_mount_link"/>
    <child link="right_gripper_flange_link"/>
  </joint>
  <link name="right_gripper_flange_link">
    <visual>
      <origin rpy="0 0 0" xyz="0 0 0"/>
      <geometry>
        <mesh filename="package://galbot_g1_description/tools/galbot_ge101in_description/meshes/v1_0_0/visual/high/right_gripper_flange_link.obj"/>
      </geometry>
    </visual>
    <inertial>
      <origin rpy="0.0 0.0 0.0" xyz="0.0030662 -1.4019e-18 3.383e-18"/>
      <mass value="0.031005"/>
      <inertia ixx="2.2585e-05" ixy="-2.0366e-21" ixz="-3.7461e-22" iyy="1.141e-05" iyz="-7.8518e-23" izz="1.141e-05"/>
    </inertial>
    <collision>
      <origin rpy="0 0 0" xyz="0 0 0"/>
      <geometry>
        <mesh filename="package://galbot_g1_description/tools/galbot_ge101in_description/meshes/v1_0_0/collision/convex_hull/right_gripper_flange_link.stl"/>
      </geometry>
    </collision>
  </link>
  <link name="right_gripper_base_link">
    <visual>
      <origin rpy="0 0 0" xyz="0 0 0"/>
      <geometry>
        <mesh filename="package://galbot_g1_description/tools/galbot_ge101in_description/meshes/v1_0_0/visual/high/right_gripper_base_link.obj"/>
      </geometry>
    </visual>
    <inertial>
      <origin rpy="0.0 0.0 0.0" xyz="0.037051 -6.4001e-05 6.4706e-05"/>
      <mass value="0.061747"/>
      <inertia ixx="2.5813e-05" ixy="4.7224e-08" ixz="-3.9403e-11" iyy="7.2859e-05" iyz="-2.962e-10" izz="5.7173e-05"/>
    </inertial>
    <collision>
      <origin rpy="0 0 0" xyz="0 0 0"/>
      <geometry>
        <mesh filename="package://galbot_g1_description/tools/galbot_ge101in_description/meshes/v1_0_0/collision/convex_hull/right_gripper_base_link.stl"/>
      </geometry>
    </collision>
  </link>
  <joint name="right_gripper_base_joint" type="fixed">
    <origin rpy="0.0 0.0 0.0" xyz="0.0065 0.0 0.0"/>
    <parent link="right_gripper_flange_link"/>
    <child link="right_gripper_base_link"/>
  </joint>
  <link name="right_gripper_l_knuckle_link">
    <visual>
      <origin rpy="0 0 0" xyz="0 0 0"/>
      <geometry>
        <mesh filename="package://galbot_g1_description/tools/galbot_ge101in_description/meshes/v1_0_0/visual/high/right_gripper_l_knuckle_link.obj"/>
      </geometry>
    </visual>
    <inertial>
      <origin rpy="0.0 0.0 0.0" xyz="0.024101 0.0 0.0"/>
      <mass value="0.0070682"/>
      <inertia ixx="9.2131e-08" ixy="0.0" ixz="0.0" iyy="1.559e-06" iyz="0.0" izz="1.4931e-06"/>
    </inertial>
    <collision>
      <origin rpy="0 0 0" xyz="0 0 0"/>
      <geometry>
        <mesh filename="package://galbot_g1_description/tools/galbot_ge101in_description/meshes/v1_0_0/collision/convex_hull/right_gripper_l_knuckle_link.stl"/>
      </geometry>
    </collision>
  </link>
  <joint name="right_gripper_l_knuckle_joint" type="revolute">
    <origin rpy="1.5707963267948966 1.2465 0.0" xyz="0.0745 0.0 -0.0385"/>
    <parent link="right_gripper_base_link"/>
    <child link="right_gripper_l_knuckle_link"/>
    <axis xyz="0.0 0.0 1.0"/>
    <limit effort="50.0" lower="-3.13" upper="3.13" velocity="0.5"/>
    <mimic joint="right_gripper_r_knuckle_joint" multiplier="1.0" offset="0.0"/>
  </joint>
  <link name="right_gripper_l_inner_knuckle_link">
    <visual>
      <origin rpy="0 0 0" xyz="0 0 0"/>
      <geometry>
        <mesh filename="package://galbot_g1_description/tools/galbot_ge101in_description/meshes/v1_0_0/visual/high/right_gripper_l_inner_knuckle_link.obj"/>
      </geometry>
    </visual>
    <inertial>
      <origin rpy="0.0 0.0 0.0" xyz="0.023769 0.0 0.0"/>
      <mass value="0.007802"/>
      <inertia ixx="1.044e-07" ixy="0.0" ixz="0.0" iyy="1.6385e-06" iyz="0.0" izz="1.566e-06"/>
    </inertial>
    <collision>
      <origin rpy="0 0 0" xyz="0 0 0"/>
      <geometry>
        <mesh filename="package://galbot_g1_description/tools/galbot_ge101in_description/meshes/v1_0_0/collision/convex_hull/right_gripper_l_inner_knuckle_link.stl"/>
      </geometry>
    </collision>
  </link>
  <joint name="right_gripper_l_inner_knuckle_joint" type="revolute">
    <origin rpy="1.5707963267948966 1.2465 0.0" xyz="0.079 0.0 -0.026"/>
    <parent link="right_gripper_base_link"/>
    <child link="right_gripper_l_inner_knuckle_link"/>
    <axis xyz="0.0 0.0 1.0"/>
    <limit effort="1000.0" lower="-3.13" upper="3.13" velocity="2.0"/>
    <mimic joint="right_gripper_r_knuckle_joint" multiplier="1.0" offset="0.0"/>
  </joint>
  <link name="right_gripper_l_finger_link">
    <visual>
      <origin rpy="0 0 0" xyz="0 0 0"/>
      <geometry>
        <mesh filename="package://galbot_g1_description/tools/galbot_ge101in_description/meshes/v1_0_0/visual/high/right_gripper_l_finger_link.obj"/>
      </geometry>
    </visual>
    <inertial>
      <origin rpy="0.0 0.0 0.0" xyz="0.016809 0.0019094 0.0"/>
      <mass value="0.015957"/>
      <inertia ixx="5.5426e-07" ixy="0.0" ixz="0.0" iyy="1.8538e-06" iyz="0.0" izz="1.5262e-06"/>
    </inertial>
    <collision>
      <origin rpy="0 0 0" xyz="0 0 0"/>
      <geometry>
        <mesh filename="package://galbot_g1_description/tools/galbot_ge101in_description/meshes/v1_0_0/collision/convex_hull/right_gripper_l_finger_link.stl"/>
      </geometry>
    </collision>
  </link>
  <joint name="right_gripper_l_finger_joint" type="revolute">
    <origin rpy="0.0 0.0 1.2465" xyz="0.045 0.0 0.0"/>
    <parent link="right_gripper_l_inner_knuckle_link"/>
    <child link="right_gripper_l_finger_link"/>
    <axis xyz="0.0 0.0 1.0"/>
    <limit effort="1000.0" lower="-3.13" upper="3.13" velocity="2.0"/>
    <mimic joint="right_gripper_r_knuckle_joint" multiplier="-1.0" offset="0.0"/>
  </joint>
  <link name="right_gripper_r_knuckle_link">
    <visual>
      <origin rpy="0 0 0" xyz="0 0 0"/>
      <geometry>
        <mesh filename="package://galbot_g1_description/tools/galbot_ge101in_description/meshes/v1_0_0/visual/high/right_gripper_r_knuckle_link.obj"/>
      </geometry>
    </visual>
    <inertial>
      <origin rpy="0.0 0.0 0.0" xyz="0.024101 0.0 0.0"/>
      <mass value="0.0070682"/>
      <inertia ixx="9.2131e-08" ixy="0.0" ixz="0.0" iyy="1.559e-06" iyz="0.0" izz="1.4931e-06"/>
    </inertial>
    <collision>
      <origin rpy="0 0 0" xyz="0 0 0"/>
      <geometry>
        <mesh filename="package://galbot_g1_description/tools/galbot_ge101in_description/meshes/v1_0_0/collision/convex_hull/right_gripper_r_knuckle_link.stl"/>
      </geometry>
    </collision>
  </link>
  <joint name="right_gripper_r_knuckle_joint" type="revolute">
    <origin rpy="1.5707963267948966 -1.2465 0.0" xyz="0.0745 0.0 0.0385"/>
    <parent link="right_gripper_base_link"/>
    <child link="right_gripper_r_knuckle_link"/>
    <axis xyz="0.0 0.0 -1.0"/>
    <limit effort="50.0" lower="0.0" upper="1.703" velocity="0.5"/>
  </joint>
  <link name="right_gripper_r_inner_knuckle_link">
    <visual>
      <origin rpy="0 0 0" xyz="0 0 0"/>
      <geometry>
        <mesh filename="package://galbot_g1_description/tools/galbot_ge101in_description/meshes/v1_0_0/visual/high/right_gripper_r_inner_knuckle_link.obj"/>
      </geometry>
    </visual>
    <inertial>
      <origin rpy="0.0 0.0 0.0" xyz="0.023769 0.0 0.0"/>
      <mass value="0.007802"/>
      <inertia ixx="1.044e-07" ixy="0.0" ixz="0.0" iyy="1.6385e-06" iyz="0.0" izz="1.566e-06"/>
    </inertial>
    <collision>
      <origin rpy="0 0 0" xyz="0 0 0"/>
      <geometry>
        <mesh filename="package://galbot_g1_description/tools/galbot_ge101in_description/meshes/v1_0_0/collision/convex_hull/right_gripper_r_inner_knuckle_link.stl"/>
      </geometry>
    </collision>
  </link>
  <joint name="right_gripper_r_inner_knuckle_joint" type="revolute">
    <origin rpy="1.5707963267948966 -1.2465 0.0" xyz="0.079 0.0 0.026"/>
    <parent link="right_gripper_base_link"/>
    <child link="right_gripper_r_inner_knuckle_link"/>
    <axis xyz="0.0 0.0 1.0"/>
    <limit effort="1000.0" lower="-3.13" upper="3.13" velocity="2.0"/>
    <mimic joint="right_gripper_r_knuckle_joint" multiplier="-1.0" offset="0.0"/>
  </joint>
  <link name="right_gripper_r_finger_link">
    <visual>
      <origin rpy="0 0 0" xyz="0 0 0"/>
      <geometry>
        <mesh filename="package://galbot_g1_description/tools/galbot_ge101in_description/meshes/v1_0_0/visual/high/right_gripper_r_finger_link.obj"/>
      </geometry>
    </visual>
    <inertial>
      <origin rpy="0.0 0.0 0.0" xyz="0.016809 -0.0019094 0.0"/>
      <mass value="0.015957"/>
      <inertia ixx="5.5426e-07" ixy="0.0" ixz="0.0" iyy="1.8538e-06" iyz="0.0" izz="1.5262e-06"/>
    </inertial>
    <collision>
      <origin rpy="0 0 0" xyz="0 0 0"/>
      <geometry>
        <mesh filename="package://galbot_g1_description/tools/galbot_ge101in_description/meshes/v1_0_0/collision/convex_hull/right_gripper_r_finger_link.stl"/>
      </geometry>
    </collision>
  </link>
  <joint name="right_gripper_r_finger_joint" type="revolute">
    <origin rpy="0.0 0.0 -1.2465" xyz="0.045 0.0 0.0"/>
    <parent link="right_gripper_r_inner_knuckle_link"/>
    <child link="right_gripper_r_finger_link"/>
    <axis xyz="0.0 0.0 1.0"/>
    <limit effort="1000.0" lower="-3.13" upper="3.13" velocity="2.0"/>
    <mimic joint="right_gripper_r_knuckle_joint" multiplier="1.0" offset="0.0"/>
  </joint>
  <link name="right_gripper_tcp_link">
    <inertial>
      <origin rpy="0.0 0.0 0.0" xyz="0.0030662 -1.4019e-18 3.383e-18"/>
      <mass value="0.031005"/>
      <inertia ixx="2.2585e-05" ixy="-2.0366e-21" ixz="-3.7461e-22" iyy="1.141e-05" iyz="-7.8518e-23" izz="1.141e-05"/>
    </inertial>
  </link>
  <joint name="right_gripper_tcp_joint" type="fixed">
    <origin rpy="-1.5707963267948966 0.0 0.0" xyz="0.13996 0.0 0.0"/>
    <parent link="right_gripper_base_link"/>
    <child link="right_gripper_tcp_link"/>
  </joint>
</robot>